[2024-06-22 15:00:31,335: INFO: main: Starting Custom logging...]
[2024-06-22 15:43:38,234: INFO: common: yaml file: config/config.yaml loaded successfully]
[2024-06-22 15:43:38,237: INFO: common: yaml file: params.yaml loaded successfully]
[2024-06-22 15:51:03,414: INFO: common: yaml file: config/config.yaml loaded successfully]
[2024-06-22 15:51:03,418: INFO: common: yaml file: params.yaml loaded successfully]
[2024-06-22 15:51:03,423: INFO: common: created directory at: artifacts]
[2024-06-22 15:51:03,433: INFO: common: created directory at: artifacts/data_ingestion]
[2024-06-22 15:51:07,250: INFO: 2391244112:  file from url https://drive.google.com/uc?/export=download&id=1RmDs2j3QcY05ixoV1-ACmxmnM5xdmiGF downloaded and saved at path artifacts/data_ingestion/card_transdata.zip]
[2024-06-22 15:51:43,659: INFO: common: yaml file: config/config.yaml loaded successfully]
[2024-06-22 15:51:43,664: INFO: common: yaml file: params.yaml loaded successfully]
[2024-06-22 15:51:43,668: INFO: common: created directory at: artifacts]
[2024-06-22 15:51:43,671: INFO: common: created directory at: artifacts/data_ingestion]
[2024-06-22 15:51:43,676: INFO: 2391244112: File already exists of size: ~ 74490 KB]
[2024-06-22 15:51:50,647: INFO: common: yaml file: config/config.yaml loaded successfully]
[2024-06-22 15:51:50,652: INFO: common: yaml file: params.yaml loaded successfully]
[2024-06-22 15:51:50,655: INFO: common: created directory at: artifacts]
[2024-06-22 15:51:50,659: INFO: common: created directory at: artifacts/data_ingestion]
[2024-06-22 15:51:50,663: INFO: 2391244112: File already exists of size: ~ 74490 KB]
[2024-06-22 15:52:10,582: INFO: common: yaml file: config/config.yaml loaded successfully]
[2024-06-22 15:52:10,587: INFO: common: yaml file: params.yaml loaded successfully]
[2024-06-22 15:52:10,596: INFO: common: created directory at: artifacts]
[2024-06-22 15:52:10,609: INFO: common: created directory at: artifacts/data_ingestion]
[2024-06-22 15:52:14,945: INFO: 2391244112:  file from url https://drive.google.com/uc?/export=download&id=1RmDs2j3QcY05ixoV1-ACmxmnM5xdmiGF downloaded and saved at path artifacts/data_ingestion/card_transdata.zip]
[2024-06-22 15:54:15,295: INFO: common: yaml file: config/config.yaml loaded successfully]
[2024-06-22 15:54:15,302: INFO: common: yaml file: params.yaml loaded successfully]
[2024-06-22 15:54:15,318: INFO: common: created directory at: artifacts]
[2024-06-22 15:54:15,325: INFO: common: created directory at: artifacts/data_ingestion]
[2024-06-22 15:54:15,336: INFO: 2494678114: File already exists of size: ~ 74490 KB]
[2024-06-22 15:54:25,557: INFO: common: yaml file: config/config.yaml loaded successfully]
[2024-06-22 15:54:25,564: INFO: common: yaml file: params.yaml loaded successfully]
[2024-06-22 15:54:25,580: INFO: common: created directory at: artifacts]
[2024-06-22 15:54:25,606: INFO: common: created directory at: artifacts/data_ingestion]
[2024-06-22 15:54:30,180: INFO: 2494678114:  file from url https://drive.google.com/uc?/export=download&id=1RmDs2j3QcY05ixoV1-ACmxmnM5xdmiGF downloaded and saved at path artifacts/data_ingestion/card_transdata.zip]
[2024-06-22 15:54:47,959: INFO: common: yaml file: config/config.yaml loaded successfully]
[2024-06-22 15:54:47,963: INFO: common: yaml file: params.yaml loaded successfully]
[2024-06-22 15:54:47,966: INFO: common: created directory at: artifacts]
[2024-06-22 15:54:47,971: INFO: common: created directory at: artifacts/data_ingestion]
[2024-06-22 15:54:47,974: INFO: 2494678114: File already exists of size: ~ 74490 KB]
[2024-06-22 15:55:32,663: INFO: common: yaml file: config/config.yaml loaded successfully]
[2024-06-22 15:55:32,669: INFO: common: yaml file: params.yaml loaded successfully]
[2024-06-22 15:55:32,681: INFO: common: created directory at: artifacts]
[2024-06-22 15:55:32,689: INFO: common: created directory at: artifacts/data_ingestion]
[2024-06-22 15:55:32,694: INFO: 2494678114: File already exists of size: ~ 4 KB]
[2024-06-22 15:56:25,554: INFO: common: yaml file: config/config.yaml loaded successfully]
[2024-06-22 15:56:25,558: INFO: common: yaml file: params.yaml loaded successfully]
[2024-06-22 15:56:25,561: INFO: common: created directory at: artifacts]
[2024-06-22 15:56:25,563: INFO: common: created directory at: artifacts/data_ingestion]
[2024-06-22 15:56:28,634: INFO: 2494678114:  file from url https://drive.google.com/uc?/export=download&id=1RmDs2j3QcY05ixoV1-ACmxmnM5xdmiGF downloaded and saved at path artifacts/data_ingestion/card_transdata.csv]
[2024-06-22 16:13:57,884: INFO: stage_01_data_ingestion: >>>>>> stage Data Ingestion stage started <<<<<<]
[2024-06-22 16:13:57,886: INFO: common: yaml file: config/config.yaml loaded successfully]
[2024-06-22 16:13:57,888: INFO: common: yaml file: params.yaml loaded successfully]
[2024-06-22 16:13:57,889: INFO: common: created directory at: artifacts]
[2024-06-22 16:13:57,890: INFO: common: created directory at: artifacts/data_ingestion]
[2024-06-22 16:13:57,892: ERROR: stage_01_data_ingestion: name 'url' is not defined]
Traceback (most recent call last):
  File "/home/nair.ro/mlops-model-dev/src/XGBClassifier/pipeline/stage_01_data_ingestion.py", line 25, in <module>
    obj.main()
  File "/home/nair.ro/mlops-model-dev/src/XGBClassifier/pipeline/stage_01_data_ingestion.py", line 16, in main
    data_ingestion.download_file()
  File "/home/nair.ro/mlops-model-dev/src/XGBClassifier/components/data_ingestion.py", line 19, in download_file
    file_id = url.split("/")[-2]
NameError: name 'url' is not defined
[2024-06-22 16:15:35,743: INFO: stage_01_data_ingestion: >>>>>> stage Data Ingestion stage started <<<<<<]
[2024-06-22 16:15:35,745: INFO: common: yaml file: config/config.yaml loaded successfully]
[2024-06-22 16:15:35,747: INFO: common: yaml file: params.yaml loaded successfully]
[2024-06-22 16:15:35,748: INFO: common: created directory at: artifacts]
[2024-06-22 16:15:35,749: INFO: common: created directory at: artifacts/data_ingestion]
[2024-06-22 16:15:35,750: ERROR: stage_01_data_ingestion: name 'gdown' is not defined]
Traceback (most recent call last):
  File "/home/nair.ro/mlops-model-dev/src/XGBClassifier/pipeline/stage_01_data_ingestion.py", line 25, in <module>
    obj.main()
  File "/home/nair.ro/mlops-model-dev/src/XGBClassifier/pipeline/stage_01_data_ingestion.py", line 16, in main
    data_ingestion.download_file()
  File "/home/nair.ro/mlops-model-dev/src/XGBClassifier/components/data_ingestion.py", line 21, in download_file
    gdown.download(prefix+file_id, self.config.local_data_file)
NameError: name 'gdown' is not defined
[2024-06-22 16:15:47,108: INFO: stage_01_data_ingestion: >>>>>> stage Data Ingestion stage started <<<<<<]
[2024-06-22 16:15:47,111: INFO: common: yaml file: config/config.yaml loaded successfully]
[2024-06-22 16:15:47,113: INFO: common: yaml file: params.yaml loaded successfully]
[2024-06-22 16:15:47,114: INFO: common: created directory at: artifacts]
[2024-06-22 16:15:47,115: INFO: common: created directory at: artifacts/data_ingestion]
[2024-06-22 16:15:47,117: ERROR: stage_01_data_ingestion: name 'gdown' is not defined]
Traceback (most recent call last):
  File "/home/nair.ro/mlops-model-dev/src/XGBClassifier/pipeline/stage_01_data_ingestion.py", line 25, in <module>
    obj.main()
  File "/home/nair.ro/mlops-model-dev/src/XGBClassifier/pipeline/stage_01_data_ingestion.py", line 16, in main
    data_ingestion.download_file()
  File "/home/nair.ro/mlops-model-dev/src/XGBClassifier/components/data_ingestion.py", line 21, in download_file
    gdown.download(prefix+file_id, self.config.local_data_file)
NameError: name 'gdown' is not defined
[2024-06-22 16:16:00,694: INFO: stage_01_data_ingestion: >>>>>> stage Data Ingestion stage started <<<<<<]
[2024-06-22 16:16:00,697: INFO: common: yaml file: config/config.yaml loaded successfully]
[2024-06-22 16:16:00,698: INFO: common: yaml file: params.yaml loaded successfully]
[2024-06-22 16:16:00,699: INFO: common: created directory at: artifacts]
[2024-06-22 16:16:00,700: INFO: common: created directory at: artifacts/data_ingestion]
[2024-06-22 16:16:04,819: INFO: data_ingestion:  file from url https://drive.google.com/uc?/export=download&id=1RmDs2j3QcY05ixoV1-ACmxmnM5xdmiGF downloaded and saved at path artifacts/data_ingestion/card_transdata.csv]
[2024-06-22 16:16:04,834: INFO: data_ingestion:  File 'artifacts/data_ingestion/card_transdata.csv' is of type '.csv']
[2024-06-22 16:16:04,835: INFO: stage_01_data_ingestion: >>>>>> stage Data Ingestion stage completed <<<<<<

x==========x]
[2024-06-22 16:19:45,704: INFO: stage_01_data_ingestion: >>>>>> stage Data Ingestion stage started <<<<<<]
[2024-06-22 16:19:45,707: INFO: common: yaml file: config/config.yaml loaded successfully]
[2024-06-22 16:19:45,711: INFO: common: yaml file: params.yaml loaded successfully]
[2024-06-22 16:19:45,713: INFO: common: created directory at: artifacts]
[2024-06-22 16:19:45,714: INFO: common: created directory at: artifacts/data_ingestion]
[2024-06-22 16:19:50,031: INFO: data_ingestion:  file from url https://drive.google.com/uc?/export=download&id=1RmDs2j3QcY05ixoV1-ACmxmnM5xdmiGF downloaded and saved at path artifacts/data_ingestion/card_transdata.csv]
[2024-06-22 16:19:50,047: INFO: data_ingestion:  File 'artifacts/data_ingestion/card_transdata.csv' is of type '.csv']
[2024-06-22 16:19:50,048: INFO: stage_01_data_ingestion: >>>>>> stage Data Ingestion stage completed <<<<<<

x==========x]
[2024-06-22 16:22:39,245: INFO: main: >>>>>> stage Data Ingestion stage started <<<<<<]
[2024-06-22 16:22:39,249: INFO: common: yaml file: config/config.yaml loaded successfully]
[2024-06-22 16:22:39,252: INFO: common: yaml file: params.yaml loaded successfully]
[2024-06-22 16:22:39,255: INFO: common: created directory at: artifacts]
[2024-06-22 16:22:39,256: INFO: common: created directory at: artifacts/data_ingestion]
[2024-06-22 16:22:42,463: INFO: data_ingestion:  file from url https://drive.google.com/uc?/export=download&id=1RmDs2j3QcY05ixoV1-ACmxmnM5xdmiGF downloaded and saved at path artifacts/data_ingestion/card_transdata.csv]
[2024-06-22 16:22:42,485: INFO: data_ingestion:  File 'artifacts/data_ingestion/card_transdata.csv' is of type '.csv']
[2024-06-22 16:22:42,486: INFO: main: >>>>>> stage Data Ingestion stage completed <<<<<<

x==========x]
[2024-06-22 17:05:08,713: INFO: stage_02_prepare_base_model: *******************]
[2024-06-22 17:05:08,713: INFO: stage_02_prepare_base_model: >>>>>> stage Prepare base model started <<<<<<]
[2024-06-22 17:05:08,717: INFO: common: yaml file: config/config.yaml loaded successfully]
[2024-06-22 17:05:08,720: INFO: common: yaml file: params.yaml loaded successfully]
[2024-06-22 17:05:08,721: INFO: common: created directory at: artifacts]
[2024-06-22 17:05:08,725: INFO: common: created directory at: artifacts/prepare_base_model]
[2024-06-22 17:05:08,725: ERROR: stage_02_prepare_base_model: "'ConfigBox' object has no attribute 'base_model_path'"]
Traceback (most recent call last):
  File "box/box.py", line 503, in box.box.Box.__getitem__
KeyError: 'base_model_path'

The above exception was the direct cause of the following exception:

Traceback (most recent call last):
  File "box/box.py", line 536, in box.box.Box.__getattr__
  File "box/box.py", line 524, in box.box.Box.__getitem__
box.exceptions.BoxKeyError: "'base_model_path'"

During handling of the above exception, another exception occurred:

Traceback (most recent call last):
  File "box/box.py", line 538, in box.box.Box.__getattr__
AttributeError: 'ConfigBox' object has no attribute 'base_model_path'

The above exception was the direct cause of the following exception:

Traceback (most recent call last):
  File "box/config_box.py", line 28, in box.config_box.ConfigBox.__getattr__
  File "box/box.py", line 552, in box.box.Box.__getattr__
box.exceptions.BoxKeyError: "'ConfigBox' object has no attribute 'base_model_path'"

During handling of the above exception, another exception occurred:

Traceback (most recent call last):
  File "box/box.py", line 503, in box.box.Box.__getitem__
KeyError: 'base_model_path'

The above exception was the direct cause of the following exception:

Traceback (most recent call last):
  File "box/box.py", line 536, in box.box.Box.__getattr__
  File "box/box.py", line 524, in box.box.Box.__getitem__
box.exceptions.BoxKeyError: "'base_model_path'"

During handling of the above exception, another exception occurred:

Traceback (most recent call last):
  File "box/box.py", line 538, in box.box.Box.__getattr__
AttributeError: 'ConfigBox' object has no attribute 'base_model_path'

The above exception was the direct cause of the following exception:

Traceback (most recent call last):
  File "/home/nair.ro/mlops-model-dev/src/XGBClassifier/pipeline/stage_02_prepare_base_model.py", line 25, in <module>
    obj.main()
  File "/home/nair.ro/mlops-model-dev/src/XGBClassifier/pipeline/stage_02_prepare_base_model.py", line 14, in main
    prepare_base_model_config = config.get_prepare_base_model_config()
  File "/home/nair.ro/ChickenDiseasaeClassification/src/cnnClassifier/config/configuration.py", line 50, in get_prepare_base_model_config
    base_model_path=Path(config.base_model_path),
  File "box/config_box.py", line 30, in box.config_box.ConfigBox.__getattr__
  File "box/box.py", line 552, in box.box.Box.__getattr__
box.exceptions.BoxKeyError: "'ConfigBox' object has no attribute 'base_model_path'"
[2024-06-22 17:09:55,499: INFO: stage_02_prepare_base_model: *******************]
[2024-06-22 17:09:55,499: INFO: stage_02_prepare_base_model: >>>>>> stage Prepare base model started <<<<<<]
[2024-06-22 17:09:55,502: INFO: common: yaml file: config/config.yaml loaded successfully]
[2024-06-22 17:09:55,506: INFO: common: yaml file: params.yaml loaded successfully]
[2024-06-22 17:09:55,507: INFO: common: created directory at: artifacts]
[2024-06-22 17:09:55,508: INFO: common: created directory at: artifacts/prepare_base_model]
[2024-06-22 17:09:55,508: ERROR: stage_02_prepare_base_model: name 'XGBClassifier' is not defined]
Traceback (most recent call last):
  File "/home/nair.ro/mlops-model-dev/src/XGBClassifier/pipeline/stage_02_prepare_base_model.py", line 26, in <module>
    obj.main()
  File "/home/nair.ro/mlops-model-dev/src/XGBClassifier/pipeline/stage_02_prepare_base_model.py", line 17, in main
    xgb = prepare_base_model.prepare_XGBClassifier_model()
  File "/home/nair.ro/mlops-model-dev/src/XGBClassifier/components/prepare_base_model.py", line 12, in prepare_XGBClassifier_model
    xgb = XGBClassifier(n_estimators=self.config.params_n_estimators ,
NameError: name 'XGBClassifier' is not defined
[2024-06-22 17:10:44,752: INFO: stage_02_prepare_base_model: *******************]
[2024-06-22 17:10:44,753: INFO: stage_02_prepare_base_model: >>>>>> stage Prepare base model started <<<<<<]
[2024-06-22 17:10:44,755: INFO: common: yaml file: config/config.yaml loaded successfully]
[2024-06-22 17:10:44,757: INFO: common: yaml file: params.yaml loaded successfully]
[2024-06-22 17:10:44,758: INFO: common: created directory at: artifacts]
[2024-06-22 17:10:44,759: INFO: common: created directory at: artifacts/prepare_base_model]
[2024-06-22 17:10:44,760: ERROR: stage_02_prepare_base_model: name 'logger' is not defined]
Traceback (most recent call last):
  File "/home/nair.ro/mlops-model-dev/src/XGBClassifier/pipeline/stage_02_prepare_base_model.py", line 26, in <module>
    obj.main()
  File "/home/nair.ro/mlops-model-dev/src/XGBClassifier/pipeline/stage_02_prepare_base_model.py", line 17, in main
    xgb = prepare_base_model.prepare_XGBClassifier_model()
  File "/home/nair.ro/mlops-model-dev/src/XGBClassifier/components/prepare_base_model.py", line 16, in prepare_XGBClassifier_model
    logger.info(f"Initialized XGBClassifier with following parameters {self.config}")
NameError: name 'logger' is not defined
[2024-06-22 17:11:02,418: INFO: stage_02_prepare_base_model: *******************]
[2024-06-22 17:11:02,419: INFO: stage_02_prepare_base_model: >>>>>> stage Prepare base model started <<<<<<]
[2024-06-22 17:11:02,421: INFO: common: yaml file: config/config.yaml loaded successfully]
[2024-06-22 17:11:02,423: INFO: common: yaml file: params.yaml loaded successfully]
[2024-06-22 17:11:02,424: INFO: common: created directory at: artifacts]
[2024-06-22 17:11:02,425: INFO: common: created directory at: artifacts/prepare_base_model]
[2024-06-22 17:11:02,426: INFO: prepare_base_model: Initialized XGBClassifier with following parameters PrepareBaseModelConfig(params_n_estimators=500, params_learning_rate=0.1, params_random_state=42, params_subsample=0.5, params_n_jobs=-1, params_max_depth=3)]
[2024-06-22 17:11:02,426: INFO: stage_02_prepare_base_model: >>>>>> stage Prepare base model completed <<<<<<

x==========x]
[2024-06-22 17:12:39,495: INFO: stage_02_prepare_base_model: *******************]
[2024-06-22 17:12:39,495: INFO: stage_02_prepare_base_model: >>>>>> stage Prepare base model started <<<<<<]
[2024-06-22 17:12:39,498: INFO: common: yaml file: config/config.yaml loaded successfully]
[2024-06-22 17:12:39,500: INFO: common: yaml file: params.yaml loaded successfully]
[2024-06-22 17:12:39,500: INFO: common: created directory at: artifacts]
[2024-06-22 17:12:39,501: INFO: common: created directory at: artifacts/prepare_base_model]
[2024-06-22 17:12:39,502: INFO: prepare_base_model: Initialized XGBClassifier with following parameters PrepareBaseModelConfig(params_n_estimators=500, params_learning_rate=0.1, params_random_state=42, params_subsample=0.5, params_n_jobs=-1, params_max_depth=3)]
[2024-06-22 17:12:39,503: INFO: stage_02_prepare_base_model: >>>>>> stage Prepare base model completed <<<<<<

x==========x]
[2024-06-22 18:10:04,182: INFO: stage_03_training_cross_val: *******************]
[2024-06-22 18:10:04,182: INFO: stage_03_training_cross_val: >>>>>> stage Training started <<<<<<]
[2024-06-22 18:10:04,184: INFO: common: yaml file: config/config.yaml loaded successfully]
[2024-06-22 18:10:04,186: INFO: common: yaml file: params.yaml loaded successfully]
[2024-06-22 18:10:04,187: INFO: common: created directory at: artifacts]
[2024-06-22 18:10:04,188: ERROR: stage_03_training_cross_val: "'ConfigBox' object has no attribute 'local_data_file'"]
Traceback (most recent call last):
  File "box/box.py", line 503, in box.box.Box.__getitem__
KeyError: 'local_data_file'

The above exception was the direct cause of the following exception:

Traceback (most recent call last):
  File "box/box.py", line 536, in box.box.Box.__getattr__
  File "box/box.py", line 524, in box.box.Box.__getitem__
box.exceptions.BoxKeyError: "'local_data_file'"

During handling of the above exception, another exception occurred:

Traceback (most recent call last):
  File "box/box.py", line 538, in box.box.Box.__getattr__
AttributeError: 'ConfigBox' object has no attribute 'local_data_file'

The above exception was the direct cause of the following exception:

Traceback (most recent call last):
  File "box/config_box.py", line 28, in box.config_box.ConfigBox.__getattr__
  File "box/box.py", line 552, in box.box.Box.__getattr__
box.exceptions.BoxKeyError: "'ConfigBox' object has no attribute 'local_data_file'"

During handling of the above exception, another exception occurred:

Traceback (most recent call last):
  File "box/box.py", line 503, in box.box.Box.__getitem__
KeyError: 'local_data_file'

The above exception was the direct cause of the following exception:

Traceback (most recent call last):
  File "box/box.py", line 536, in box.box.Box.__getattr__
  File "box/box.py", line 524, in box.box.Box.__getitem__
box.exceptions.BoxKeyError: "'local_data_file'"

During handling of the above exception, another exception occurred:

Traceback (most recent call last):
  File "box/box.py", line 538, in box.box.Box.__getattr__
AttributeError: 'ConfigBox' object has no attribute 'local_data_file'

The above exception was the direct cause of the following exception:

Traceback (most recent call last):
  File "/home/nair.ro/mlops-model-dev/src/XGBClassifier/pipeline/stage_03_training_cross_val.py", line 30, in <module>
    obj.main()
  File "/home/nair.ro/mlops-model-dev/src/XGBClassifier/pipeline/stage_03_training_cross_val.py", line 16, in main
    training_config = config.get_training_config()
  File "/home/nair.ro/mlops-model-dev/src/XGBClassifier/config_mngr/configuration_manager.py", line 60, in get_training_config
    training_data = self.config.local_data_file
  File "box/config_box.py", line 30, in box.config_box.ConfigBox.__getattr__
  File "box/box.py", line 552, in box.box.Box.__getattr__
box.exceptions.BoxKeyError: "'ConfigBox' object has no attribute 'local_data_file'"
[2024-06-22 18:10:09,490: INFO: stage_03_training_cross_val: *******************]
[2024-06-22 18:10:09,490: INFO: stage_03_training_cross_val: >>>>>> stage Training started <<<<<<]
[2024-06-22 18:10:09,492: INFO: common: yaml file: config/config.yaml loaded successfully]
[2024-06-22 18:10:09,494: INFO: common: yaml file: params.yaml loaded successfully]
[2024-06-22 18:10:09,495: INFO: common: created directory at: artifacts]
[2024-06-22 18:10:09,496: ERROR: stage_03_training_cross_val: "'ConfigBox' object has no attribute 'local_data_file'"]
Traceback (most recent call last):
  File "box/box.py", line 503, in box.box.Box.__getitem__
KeyError: 'local_data_file'

The above exception was the direct cause of the following exception:

Traceback (most recent call last):
  File "box/box.py", line 536, in box.box.Box.__getattr__
  File "box/box.py", line 524, in box.box.Box.__getitem__
box.exceptions.BoxKeyError: "'local_data_file'"

During handling of the above exception, another exception occurred:

Traceback (most recent call last):
  File "box/box.py", line 538, in box.box.Box.__getattr__
AttributeError: 'ConfigBox' object has no attribute 'local_data_file'

The above exception was the direct cause of the following exception:

Traceback (most recent call last):
  File "box/config_box.py", line 28, in box.config_box.ConfigBox.__getattr__
  File "box/box.py", line 552, in box.box.Box.__getattr__
box.exceptions.BoxKeyError: "'ConfigBox' object has no attribute 'local_data_file'"

During handling of the above exception, another exception occurred:

Traceback (most recent call last):
  File "box/box.py", line 503, in box.box.Box.__getitem__
KeyError: 'local_data_file'

The above exception was the direct cause of the following exception:

Traceback (most recent call last):
  File "box/box.py", line 536, in box.box.Box.__getattr__
  File "box/box.py", line 524, in box.box.Box.__getitem__
box.exceptions.BoxKeyError: "'local_data_file'"

During handling of the above exception, another exception occurred:

Traceback (most recent call last):
  File "box/box.py", line 538, in box.box.Box.__getattr__
AttributeError: 'ConfigBox' object has no attribute 'local_data_file'

The above exception was the direct cause of the following exception:

Traceback (most recent call last):
  File "/home/nair.ro/mlops-model-dev/src/XGBClassifier/pipeline/stage_03_training_cross_val.py", line 30, in <module>
    obj.main()
  File "/home/nair.ro/mlops-model-dev/src/XGBClassifier/pipeline/stage_03_training_cross_val.py", line 16, in main
    training_config = config.get_training_config()
  File "/home/nair.ro/mlops-model-dev/src/XGBClassifier/config_mngr/configuration_manager.py", line 60, in get_training_config
    training_data = self.config.local_data_file
  File "box/config_box.py", line 30, in box.config_box.ConfigBox.__getattr__
  File "box/box.py", line 552, in box.box.Box.__getattr__
box.exceptions.BoxKeyError: "'ConfigBox' object has no attribute 'local_data_file'"
[2024-06-22 18:16:28,160: INFO: stage_03_training_cross_val: *******************]
[2024-06-22 18:16:28,160: INFO: stage_03_training_cross_val: >>>>>> stage Training started <<<<<<]
[2024-06-22 18:16:28,169: INFO: common: yaml file: config/config.yaml loaded successfully]
[2024-06-22 18:16:28,172: INFO: common: yaml file: params.yaml loaded successfully]
[2024-06-22 18:16:28,173: INFO: common: created directory at: artifacts]
[2024-06-22 18:16:28,173: ERROR: stage_03_training_cross_val: "'ConfigBox' object has no attribute 'local_data_file'"]
Traceback (most recent call last):
  File "box/box.py", line 503, in box.box.Box.__getitem__
KeyError: 'local_data_file'

The above exception was the direct cause of the following exception:

Traceback (most recent call last):
  File "box/box.py", line 536, in box.box.Box.__getattr__
  File "box/box.py", line 524, in box.box.Box.__getitem__
box.exceptions.BoxKeyError: "'local_data_file'"

During handling of the above exception, another exception occurred:

Traceback (most recent call last):
  File "box/box.py", line 538, in box.box.Box.__getattr__
AttributeError: 'ConfigBox' object has no attribute 'local_data_file'

The above exception was the direct cause of the following exception:

Traceback (most recent call last):
  File "box/config_box.py", line 28, in box.config_box.ConfigBox.__getattr__
  File "box/box.py", line 552, in box.box.Box.__getattr__
box.exceptions.BoxKeyError: "'ConfigBox' object has no attribute 'local_data_file'"

During handling of the above exception, another exception occurred:

Traceback (most recent call last):
  File "box/box.py", line 503, in box.box.Box.__getitem__
KeyError: 'local_data_file'

The above exception was the direct cause of the following exception:

Traceback (most recent call last):
  File "box/box.py", line 536, in box.box.Box.__getattr__
  File "box/box.py", line 524, in box.box.Box.__getitem__
box.exceptions.BoxKeyError: "'local_data_file'"

During handling of the above exception, another exception occurred:

Traceback (most recent call last):
  File "box/box.py", line 538, in box.box.Box.__getattr__
AttributeError: 'ConfigBox' object has no attribute 'local_data_file'

The above exception was the direct cause of the following exception:

Traceback (most recent call last):
  File "/home/nair.ro/mlops-model-dev/src/XGBClassifier/pipeline/stage_03_training_cross_val.py", line 30, in <module>
    obj.main()
  File "/home/nair.ro/mlops-model-dev/src/XGBClassifier/pipeline/stage_03_training_cross_val.py", line 16, in main
    training_config = config.get_training_config()
  File "/home/nair.ro/mlops-model-dev/src/XGBClassifier/config_mngr/configuration_manager.py", line 60, in get_training_config
    training_data = self.config.local_data_file
  File "box/config_box.py", line 30, in box.config_box.ConfigBox.__getattr__
  File "box/box.py", line 552, in box.box.Box.__getattr__
box.exceptions.BoxKeyError: "'ConfigBox' object has no attribute 'local_data_file'"
[2024-06-22 18:18:59,007: INFO: stage_01_data_ingestion: >>>>>> stage Data Ingestion stage started <<<<<<]
[2024-06-22 18:18:59,010: INFO: common: yaml file: config/config.yaml loaded successfully]
[2024-06-22 18:18:59,012: INFO: common: yaml file: params.yaml loaded successfully]
[2024-06-22 18:18:59,014: INFO: common: created directory at: artifacts]
[2024-06-22 18:18:59,015: INFO: common: created directory at: artifacts/data_ingestion]
[2024-06-22 18:19:04,608: INFO: data_ingestion:  file from url https://drive.google.com/uc?/export=download&id=1RmDs2j3QcY05ixoV1-ACmxmnM5xdmiGF downloaded and saved at path artifacts/data_ingestion/card_transdata.csv]
[2024-06-22 18:19:04,624: INFO: data_ingestion:  File 'artifacts/data_ingestion/card_transdata.csv' is of type '.csv']
[2024-06-22 18:19:04,624: INFO: stage_01_data_ingestion: >>>>>> stage Data Ingestion stage completed <<<<<<

x==========x]
[2024-06-22 18:19:15,699: INFO: stage_02_prepare_base_model: *******************]
[2024-06-22 18:19:15,700: INFO: stage_02_prepare_base_model: >>>>>> stage Prepare base model started <<<<<<]
[2024-06-22 18:19:15,702: INFO: common: yaml file: config/config.yaml loaded successfully]
[2024-06-22 18:19:15,707: INFO: common: yaml file: params.yaml loaded successfully]
[2024-06-22 18:19:15,709: INFO: common: created directory at: artifacts]
[2024-06-22 18:19:15,710: INFO: common: created directory at: artifacts/prepare_base_model]
[2024-06-22 18:19:15,710: INFO: prepare_base_model: Initialized XGBClassifier with following parameters PrepareBaseModelConfig(params_n_estimators=500, params_learning_rate=0.1, params_random_state=42, params_subsample=0.5, params_n_jobs=-1, params_max_depth=3)]
[2024-06-22 18:19:15,710: INFO: stage_02_prepare_base_model: >>>>>> stage Prepare base model completed <<<<<<

x==========x]
[2024-06-22 18:19:23,864: INFO: stage_03_training_cross_val: *******************]
[2024-06-22 18:19:23,865: INFO: stage_03_training_cross_val: >>>>>> stage Training started <<<<<<]
[2024-06-22 18:19:23,867: INFO: common: yaml file: config/config.yaml loaded successfully]
[2024-06-22 18:19:23,873: INFO: common: yaml file: params.yaml loaded successfully]
[2024-06-22 18:19:23,875: INFO: common: created directory at: artifacts]
[2024-06-22 18:19:23,876: ERROR: stage_03_training_cross_val: "'ConfigBox' object has no attribute 'local_data_file'"]
Traceback (most recent call last):
  File "box/box.py", line 503, in box.box.Box.__getitem__
KeyError: 'local_data_file'

The above exception was the direct cause of the following exception:

Traceback (most recent call last):
  File "box/box.py", line 536, in box.box.Box.__getattr__
  File "box/box.py", line 524, in box.box.Box.__getitem__
box.exceptions.BoxKeyError: "'local_data_file'"

During handling of the above exception, another exception occurred:

Traceback (most recent call last):
  File "box/box.py", line 538, in box.box.Box.__getattr__
AttributeError: 'ConfigBox' object has no attribute 'local_data_file'

The above exception was the direct cause of the following exception:

Traceback (most recent call last):
  File "box/config_box.py", line 28, in box.config_box.ConfigBox.__getattr__
  File "box/box.py", line 552, in box.box.Box.__getattr__
box.exceptions.BoxKeyError: "'ConfigBox' object has no attribute 'local_data_file'"

During handling of the above exception, another exception occurred:

Traceback (most recent call last):
  File "box/box.py", line 503, in box.box.Box.__getitem__
KeyError: 'local_data_file'

The above exception was the direct cause of the following exception:

Traceback (most recent call last):
  File "box/box.py", line 536, in box.box.Box.__getattr__
  File "box/box.py", line 524, in box.box.Box.__getitem__
box.exceptions.BoxKeyError: "'local_data_file'"

During handling of the above exception, another exception occurred:

Traceback (most recent call last):
  File "box/box.py", line 538, in box.box.Box.__getattr__
AttributeError: 'ConfigBox' object has no attribute 'local_data_file'

The above exception was the direct cause of the following exception:

Traceback (most recent call last):
  File "/home/nair.ro/mlops-model-dev/src/XGBClassifier/pipeline/stage_03_training_cross_val.py", line 30, in <module>
    obj.main()
  File "/home/nair.ro/mlops-model-dev/src/XGBClassifier/pipeline/stage_03_training_cross_val.py", line 16, in main
    training_config = config.get_training_config()
  File "/home/nair.ro/mlops-model-dev/src/XGBClassifier/config_mngr/configuration_manager.py", line 60, in get_training_config
    training_data = self.config.local_data_file
  File "box/config_box.py", line 30, in box.config_box.ConfigBox.__getattr__
  File "box/box.py", line 552, in box.box.Box.__getattr__
box.exceptions.BoxKeyError: "'ConfigBox' object has no attribute 'local_data_file'"
[2024-06-22 18:20:21,914: INFO: stage_03_training_cross_val: *******************]
[2024-06-22 18:20:21,914: INFO: stage_03_training_cross_val: >>>>>> stage Training started <<<<<<]
[2024-06-22 18:20:21,917: INFO: common: yaml file: config/config.yaml loaded successfully]
[2024-06-22 18:20:21,920: INFO: common: yaml file: params.yaml loaded successfully]
[2024-06-22 18:20:21,921: INFO: common: created directory at: artifacts]
[2024-06-22 18:20:21,921: ERROR: stage_03_training_cross_val: "'ConfigBox' object has no attribute 'local_data_file'"]
Traceback (most recent call last):
  File "box/box.py", line 503, in box.box.Box.__getitem__
KeyError: 'local_data_file'

The above exception was the direct cause of the following exception:

Traceback (most recent call last):
  File "box/box.py", line 536, in box.box.Box.__getattr__
  File "box/box.py", line 524, in box.box.Box.__getitem__
box.exceptions.BoxKeyError: "'local_data_file'"

During handling of the above exception, another exception occurred:

Traceback (most recent call last):
  File "box/box.py", line 538, in box.box.Box.__getattr__
AttributeError: 'ConfigBox' object has no attribute 'local_data_file'

The above exception was the direct cause of the following exception:

Traceback (most recent call last):
  File "box/config_box.py", line 28, in box.config_box.ConfigBox.__getattr__
  File "box/box.py", line 552, in box.box.Box.__getattr__
box.exceptions.BoxKeyError: "'ConfigBox' object has no attribute 'local_data_file'"

During handling of the above exception, another exception occurred:

Traceback (most recent call last):
  File "box/box.py", line 503, in box.box.Box.__getitem__
KeyError: 'local_data_file'

The above exception was the direct cause of the following exception:

Traceback (most recent call last):
  File "box/box.py", line 536, in box.box.Box.__getattr__
  File "box/box.py", line 524, in box.box.Box.__getitem__
box.exceptions.BoxKeyError: "'local_data_file'"

During handling of the above exception, another exception occurred:

Traceback (most recent call last):
  File "box/box.py", line 538, in box.box.Box.__getattr__
AttributeError: 'ConfigBox' object has no attribute 'local_data_file'

The above exception was the direct cause of the following exception:

Traceback (most recent call last):
  File "/home/nair.ro/mlops-model-dev/src/XGBClassifier/pipeline/stage_03_training_cross_val.py", line 30, in <module>
    obj.main()
  File "/home/nair.ro/mlops-model-dev/src/XGBClassifier/pipeline/stage_03_training_cross_val.py", line 16, in main
    training_config = config.get_training_config()
  File "/home/nair.ro/mlops-model-dev/src/XGBClassifier/config_mngr/configuration_manager.py", line 60, in get_training_config
    training_data = self.config.local_data_file
  File "box/config_box.py", line 30, in box.config_box.ConfigBox.__getattr__
  File "box/box.py", line 552, in box.box.Box.__getattr__
box.exceptions.BoxKeyError: "'ConfigBox' object has no attribute 'local_data_file'"
[2024-06-22 18:22:52,234: INFO: stage_03_training_cross_val: *******************]
[2024-06-22 18:22:52,235: INFO: stage_03_training_cross_val: >>>>>> stage Training started <<<<<<]
[2024-06-22 18:22:52,238: INFO: common: yaml file: config/config.yaml loaded successfully]
[2024-06-22 18:22:52,242: INFO: common: yaml file: params.yaml loaded successfully]
[2024-06-22 18:22:52,243: INFO: common: created directory at: artifacts]
[2024-06-22 18:22:52,246: INFO: common: created directory at: artifacts/training]
[2024-06-22 18:22:52,247: ERROR: stage_03_training_cross_val: TrainingConfig.__init__() got an unexpected keyword argument 'params_scoring']
Traceback (most recent call last):
  File "/home/nair.ro/mlops-model-dev/src/XGBClassifier/pipeline/stage_03_training_cross_val.py", line 30, in <module>
    obj.main()
  File "/home/nair.ro/mlops-model-dev/src/XGBClassifier/pipeline/stage_03_training_cross_val.py", line 16, in main
    training_config = config.get_training_config()
  File "/home/nair.ro/mlops-model-dev/src/XGBClassifier/config_mngr/configuration_manager.py", line 65, in get_training_config
    training_config = TrainingConfig(
TypeError: TrainingConfig.__init__() got an unexpected keyword argument 'params_scoring'
[2024-06-22 18:22:57,488: INFO: stage_03_training_cross_val: *******************]
[2024-06-22 18:22:57,489: INFO: stage_03_training_cross_val: >>>>>> stage Training started <<<<<<]
[2024-06-22 18:22:57,491: INFO: common: yaml file: config/config.yaml loaded successfully]
[2024-06-22 18:22:57,493: INFO: common: yaml file: params.yaml loaded successfully]
[2024-06-22 18:22:57,493: INFO: common: created directory at: artifacts]
[2024-06-22 18:22:57,496: INFO: common: created directory at: artifacts/training]
[2024-06-22 18:22:57,496: ERROR: stage_03_training_cross_val: TrainingConfig.__init__() got an unexpected keyword argument 'params_scoring']
Traceback (most recent call last):
  File "/home/nair.ro/mlops-model-dev/src/XGBClassifier/pipeline/stage_03_training_cross_val.py", line 30, in <module>
    obj.main()
  File "/home/nair.ro/mlops-model-dev/src/XGBClassifier/pipeline/stage_03_training_cross_val.py", line 16, in main
    training_config = config.get_training_config()
  File "/home/nair.ro/mlops-model-dev/src/XGBClassifier/config_mngr/configuration_manager.py", line 65, in get_training_config
    training_config = TrainingConfig(
TypeError: TrainingConfig.__init__() got an unexpected keyword argument 'params_scoring'
[2024-06-22 18:23:50,914: INFO: stage_03_training_cross_val: *******************]
[2024-06-22 18:23:50,915: INFO: stage_03_training_cross_val: >>>>>> stage Training started <<<<<<]
[2024-06-22 18:23:50,921: INFO: common: yaml file: config/config.yaml loaded successfully]
[2024-06-22 18:23:50,926: INFO: common: yaml file: params.yaml loaded successfully]
[2024-06-22 18:23:50,927: INFO: common: created directory at: artifacts]
[2024-06-22 18:23:50,929: INFO: common: created directory at: artifacts/training]
[2024-06-22 18:23:50,929: ERROR: stage_03_training_cross_val: TrainingConfig.__init__() got an unexpected keyword argument 'params_cv']
Traceback (most recent call last):
  File "/home/nair.ro/mlops-model-dev/src/XGBClassifier/pipeline/stage_03_training_cross_val.py", line 30, in <module>
    obj.main()
  File "/home/nair.ro/mlops-model-dev/src/XGBClassifier/pipeline/stage_03_training_cross_val.py", line 16, in main
    training_config = config.get_training_config()
  File "/home/nair.ro/mlops-model-dev/src/XGBClassifier/config_mngr/configuration_manager.py", line 65, in get_training_config
    training_config = TrainingConfig(
TypeError: TrainingConfig.__init__() got an unexpected keyword argument 'params_cv'
[2024-06-22 18:26:05,550: INFO: stage_03_training_cross_val: *******************]
[2024-06-22 18:26:05,551: INFO: stage_03_training_cross_val: >>>>>> stage Training started <<<<<<]
[2024-06-22 18:26:05,557: INFO: common: yaml file: config/config.yaml loaded successfully]
[2024-06-22 18:26:05,561: INFO: common: yaml file: params.yaml loaded successfully]
[2024-06-22 18:26:05,562: INFO: common: created directory at: artifacts]
[2024-06-22 18:26:05,564: INFO: common: created directory at: artifacts/training]
[2024-06-22 18:26:05,565: ERROR: stage_03_training_cross_val: name 'xgb' is not defined]
Traceback (most recent call last):
  File "/home/nair.ro/mlops-model-dev/src/XGBClassifier/pipeline/stage_03_training_cross_val.py", line 30, in <module>
    obj.main()
  File "/home/nair.ro/mlops-model-dev/src/XGBClassifier/pipeline/stage_03_training_cross_val.py", line 19, in main
    training.train(xgb)
NameError: name 'xgb' is not defined
[2024-06-22 18:27:29,952: INFO: main: >>>>>> stage Data Ingestion stage started <<<<<<]
[2024-06-22 18:27:29,957: INFO: common: yaml file: config/config.yaml loaded successfully]
[2024-06-22 18:27:29,966: INFO: common: yaml file: params.yaml loaded successfully]
[2024-06-22 18:27:29,967: INFO: common: created directory at: artifacts]
[2024-06-22 18:27:29,972: INFO: common: created directory at: artifacts/data_ingestion]
[2024-06-22 18:27:29,974: INFO: data_ingestion: File already exists of size: ~ 74490 KB]
[2024-06-22 18:27:29,979: INFO: data_ingestion:  File 'artifacts/data_ingestion/card_transdata.csv' is of type '.csv']
[2024-06-22 18:27:29,979: INFO: main: >>>>>> stage Data Ingestion stage completed <<<<<<

x==========x]
[2024-06-22 18:27:29,980: INFO: main: *******************]
[2024-06-22 18:27:29,980: INFO: main: >>>>>> stage Prepare base model started <<<<<<]
[2024-06-22 18:27:29,981: ERROR: main: name 'PrepareBaseModelTrainingPipeline' is not defined]
Traceback (most recent call last):
  File "/home/nair.ro/mlops-model-dev/main.py", line 23, in <module>
    prepare_base_model = PrepareBaseModelTrainingPipeline()
NameError: name 'PrepareBaseModelTrainingPipeline' is not defined
[2024-06-22 18:27:40,726: INFO: main: >>>>>> stage Data Ingestion stage started <<<<<<]
[2024-06-22 18:27:40,732: INFO: common: yaml file: config/config.yaml loaded successfully]
[2024-06-22 18:27:40,736: INFO: common: yaml file: params.yaml loaded successfully]
[2024-06-22 18:27:40,740: INFO: common: created directory at: artifacts]
[2024-06-22 18:27:40,742: INFO: common: created directory at: artifacts/data_ingestion]
[2024-06-22 18:27:40,743: INFO: data_ingestion: File already exists of size: ~ 74490 KB]
[2024-06-22 18:27:40,747: INFO: data_ingestion:  File 'artifacts/data_ingestion/card_transdata.csv' is of type '.csv']
[2024-06-22 18:27:40,747: INFO: main: >>>>>> stage Data Ingestion stage completed <<<<<<

x==========x]
[2024-06-22 18:27:40,748: INFO: main: *******************]
[2024-06-22 18:27:40,748: INFO: main: >>>>>> stage Prepare base model started <<<<<<]
[2024-06-22 18:27:40,748: ERROR: main: name 'PrepareBaseModelTrainingPipeline' is not defined]
Traceback (most recent call last):
  File "/home/nair.ro/mlops-model-dev/main.py", line 23, in <module>
    prepare_base_model = PrepareBaseModelTrainingPipeline()
NameError: name 'PrepareBaseModelTrainingPipeline' is not defined
[2024-06-22 18:29:05,397: INFO: main: >>>>>> stage Data Ingestion stage started <<<<<<]
[2024-06-22 18:29:05,405: INFO: common: yaml file: config/config.yaml loaded successfully]
[2024-06-22 18:29:05,415: INFO: common: yaml file: params.yaml loaded successfully]
[2024-06-22 18:29:05,417: INFO: common: created directory at: artifacts]
[2024-06-22 18:29:05,422: INFO: common: created directory at: artifacts/data_ingestion]
[2024-06-22 18:29:05,425: INFO: data_ingestion: File already exists of size: ~ 74490 KB]
[2024-06-22 18:29:05,430: INFO: data_ingestion:  File 'artifacts/data_ingestion/card_transdata.csv' is of type '.csv']
[2024-06-22 18:29:05,433: INFO: main: >>>>>> stage Data Ingestion stage completed <<<<<<

x==========x]
[2024-06-22 18:29:05,434: INFO: main: *******************]
[2024-06-22 18:29:05,434: INFO: main: >>>>>> stage Prepare base model started <<<<<<]
[2024-06-22 18:29:05,440: INFO: common: yaml file: config/config.yaml loaded successfully]
[2024-06-22 18:29:05,444: INFO: common: yaml file: params.yaml loaded successfully]
[2024-06-22 18:29:05,445: INFO: common: created directory at: artifacts]
[2024-06-22 18:29:05,447: INFO: common: created directory at: artifacts/prepare_base_model]
[2024-06-22 18:29:05,448: INFO: prepare_base_model: Initialized XGBClassifier with following parameters PrepareBaseModelConfig(params_n_estimators=500, params_learning_rate=0.1, params_random_state=42, params_subsample=0.5, params_n_jobs=-1, params_max_depth=3)]
[2024-06-22 18:29:05,448: INFO: main: >>>>>> stage Prepare base model completed <<<<<<

x==========x]
[2024-06-22 18:29:05,449: INFO: main: *******************]
[2024-06-22 18:29:05,449: INFO: main: >>>>>> stage Train and save model started <<<<<<]
[2024-06-22 18:29:05,452: INFO: common: yaml file: config/config.yaml loaded successfully]
[2024-06-22 18:29:05,457: INFO: common: yaml file: params.yaml loaded successfully]
[2024-06-22 18:29:05,459: INFO: common: created directory at: artifacts]
[2024-06-22 18:29:05,460: INFO: common: created directory at: artifacts/training]
[2024-06-22 18:29:05,461: ERROR: main: name 'train_valid_generator' is not defined]
Traceback (most recent call last):
  File "/home/nair.ro/mlops-model-dev/main.py", line 38, in <module>
    obj.main(xgb)
  File "/home/nair.ro/mlops-model-dev/src/XGBClassifier/pipeline/stage_03_training_cross_val.py", line 19, in main
    training.train(xgb)
  File "/home/nair.ro/mlops-model-dev/src/XGBClassifier/components/training.py", line 37, in train
    X_train , X_test ,y_train , y_test  = train_valid_generator()
NameError: name 'train_valid_generator' is not defined
[2024-06-22 18:30:40,463: INFO: main: >>>>>> stage Data Ingestion stage started <<<<<<]
[2024-06-22 18:30:40,471: INFO: common: yaml file: config/config.yaml loaded successfully]
[2024-06-22 18:30:40,477: INFO: common: yaml file: params.yaml loaded successfully]
[2024-06-22 18:30:40,480: INFO: common: created directory at: artifacts]
[2024-06-22 18:30:40,482: INFO: common: created directory at: artifacts/data_ingestion]
[2024-06-22 18:30:40,485: INFO: data_ingestion: File already exists of size: ~ 74490 KB]
[2024-06-22 18:30:40,489: INFO: data_ingestion:  File 'artifacts/data_ingestion/card_transdata.csv' is of type '.csv']
[2024-06-22 18:30:40,489: INFO: main: >>>>>> stage Data Ingestion stage completed <<<<<<

x==========x]
[2024-06-22 18:30:40,490: INFO: main: *******************]
[2024-06-22 18:30:40,490: INFO: main: >>>>>> stage Prepare base model started <<<<<<]
[2024-06-22 18:30:40,493: INFO: common: yaml file: config/config.yaml loaded successfully]
[2024-06-22 18:30:40,496: INFO: common: yaml file: params.yaml loaded successfully]
[2024-06-22 18:30:40,497: INFO: common: created directory at: artifacts]
[2024-06-22 18:30:40,499: INFO: common: created directory at: artifacts/prepare_base_model]
[2024-06-22 18:30:40,500: INFO: prepare_base_model: Initialized XGBClassifier with following parameters PrepareBaseModelConfig(params_n_estimators=500, params_learning_rate=0.1, params_random_state=42, params_subsample=0.5, params_n_jobs=-1, params_max_depth=3)]
[2024-06-22 18:30:40,500: INFO: main: >>>>>> stage Prepare base model completed <<<<<<

x==========x]
[2024-06-22 18:30:40,500: INFO: main: *******************]
[2024-06-22 18:30:40,500: INFO: main: >>>>>> stage Train and save model started <<<<<<]
[2024-06-22 18:30:40,503: INFO: common: yaml file: config/config.yaml loaded successfully]
[2024-06-22 18:30:40,507: INFO: common: yaml file: params.yaml loaded successfully]
[2024-06-22 18:30:40,510: INFO: common: created directory at: artifacts]
[2024-06-22 18:30:40,512: INFO: common: created directory at: artifacts/training]
[2024-06-22 18:30:40,513: ERROR: main: name 'pd' is not defined]
Traceback (most recent call last):
  File "/home/nair.ro/mlops-model-dev/main.py", line 38, in <module>
    obj.main(xgb)
  File "/home/nair.ro/mlops-model-dev/src/XGBClassifier/pipeline/stage_03_training_cross_val.py", line 19, in main
    training.train(xgb)
  File "/home/nair.ro/mlops-model-dev/src/XGBClassifier/components/training.py", line 37, in train
    X_train , X_test ,y_train , y_test  = self.train_valid_generator()
  File "/home/nair.ro/mlops-model-dev/src/XGBClassifier/components/training.py", line 12, in train_valid_generator
    df = pd.read_csv(self.config.training_data,encoding='utf-8')
NameError: name 'pd' is not defined
[2024-06-22 18:31:05,232: INFO: main: >>>>>> stage Data Ingestion stage started <<<<<<]
[2024-06-22 18:31:05,237: INFO: common: yaml file: config/config.yaml loaded successfully]
[2024-06-22 18:31:05,241: INFO: common: yaml file: params.yaml loaded successfully]
[2024-06-22 18:31:05,242: INFO: common: created directory at: artifacts]
[2024-06-22 18:31:05,243: INFO: common: created directory at: artifacts/data_ingestion]
[2024-06-22 18:31:05,244: INFO: data_ingestion: File already exists of size: ~ 74490 KB]
[2024-06-22 18:31:05,245: INFO: data_ingestion:  File 'artifacts/data_ingestion/card_transdata.csv' is of type '.csv']
[2024-06-22 18:31:05,246: INFO: main: >>>>>> stage Data Ingestion stage completed <<<<<<

x==========x]
[2024-06-22 18:31:05,246: INFO: main: *******************]
[2024-06-22 18:31:05,246: INFO: main: >>>>>> stage Prepare base model started <<<<<<]
[2024-06-22 18:31:05,250: INFO: common: yaml file: config/config.yaml loaded successfully]
[2024-06-22 18:31:05,252: INFO: common: yaml file: params.yaml loaded successfully]
[2024-06-22 18:31:05,254: INFO: common: created directory at: artifacts]
[2024-06-22 18:31:05,255: INFO: common: created directory at: artifacts/prepare_base_model]
[2024-06-22 18:31:05,255: INFO: prepare_base_model: Initialized XGBClassifier with following parameters PrepareBaseModelConfig(params_n_estimators=500, params_learning_rate=0.1, params_random_state=42, params_subsample=0.5, params_n_jobs=-1, params_max_depth=3)]
[2024-06-22 18:31:05,256: INFO: main: >>>>>> stage Prepare base model completed <<<<<<

x==========x]
[2024-06-22 18:31:05,256: INFO: main: *******************]
[2024-06-22 18:31:05,256: INFO: main: >>>>>> stage Train and save model started <<<<<<]
[2024-06-22 18:31:05,259: INFO: common: yaml file: config/config.yaml loaded successfully]
[2024-06-22 18:31:05,263: INFO: common: yaml file: params.yaml loaded successfully]
[2024-06-22 18:31:05,263: INFO: common: created directory at: artifacts]
[2024-06-22 18:31:05,264: INFO: common: created directory at: artifacts/training]
[2024-06-22 18:31:06,260: ERROR: main: name 'train_test_split' is not defined]
Traceback (most recent call last):
  File "/home/nair.ro/mlops-model-dev/main.py", line 38, in <module>
    obj.main(xgb)
  File "/home/nair.ro/mlops-model-dev/src/XGBClassifier/pipeline/stage_03_training_cross_val.py", line 19, in main
    training.train(xgb)
  File "/home/nair.ro/mlops-model-dev/src/XGBClassifier/components/training.py", line 37, in train
    X_train , X_test ,y_train , y_test  = self.train_valid_generator()
  File "/home/nair.ro/mlops-model-dev/src/XGBClassifier/components/training.py", line 18, in train_valid_generator
    X_train , X_test ,y_train , y_test = train_test_split(X,y,test_size = 0.2 ,random_state = 42 ,stratify=y)
NameError: name 'train_test_split' is not defined
[2024-06-22 18:31:39,666: INFO: main: >>>>>> stage Data Ingestion stage started <<<<<<]
[2024-06-22 18:31:39,669: INFO: common: yaml file: config/config.yaml loaded successfully]
[2024-06-22 18:31:39,670: INFO: common: yaml file: params.yaml loaded successfully]
[2024-06-22 18:31:39,672: INFO: common: created directory at: artifacts]
[2024-06-22 18:31:39,673: INFO: common: created directory at: artifacts/data_ingestion]
[2024-06-22 18:31:39,673: INFO: data_ingestion: File already exists of size: ~ 74490 KB]
[2024-06-22 18:31:39,675: INFO: data_ingestion:  File 'artifacts/data_ingestion/card_transdata.csv' is of type '.csv']
[2024-06-22 18:31:39,675: INFO: main: >>>>>> stage Data Ingestion stage completed <<<<<<

x==========x]
[2024-06-22 18:31:39,675: INFO: main: *******************]
[2024-06-22 18:31:39,676: INFO: main: >>>>>> stage Prepare base model started <<<<<<]
[2024-06-22 18:31:39,679: INFO: common: yaml file: config/config.yaml loaded successfully]
[2024-06-22 18:31:39,681: INFO: common: yaml file: params.yaml loaded successfully]
[2024-06-22 18:31:39,682: INFO: common: created directory at: artifacts]
[2024-06-22 18:31:39,687: INFO: common: created directory at: artifacts/prepare_base_model]
[2024-06-22 18:31:39,687: INFO: prepare_base_model: Initialized XGBClassifier with following parameters PrepareBaseModelConfig(params_n_estimators=500, params_learning_rate=0.1, params_random_state=42, params_subsample=0.5, params_n_jobs=-1, params_max_depth=3)]
[2024-06-22 18:31:39,687: INFO: main: >>>>>> stage Prepare base model completed <<<<<<

x==========x]
[2024-06-22 18:31:39,688: INFO: main: *******************]
[2024-06-22 18:31:39,688: INFO: main: >>>>>> stage Train and save model started <<<<<<]
[2024-06-22 18:31:39,691: INFO: common: yaml file: config/config.yaml loaded successfully]
[2024-06-22 18:31:39,693: INFO: common: yaml file: params.yaml loaded successfully]
[2024-06-22 18:31:39,694: INFO: common: created directory at: artifacts]
[2024-06-22 18:31:39,695: INFO: common: created directory at: artifacts/training]
[2024-06-22 18:31:41,008: ERROR: main: name 'logger' is not defined]
Traceback (most recent call last):
  File "/home/nair.ro/mlops-model-dev/main.py", line 38, in <module>
    obj.main(xgb)
  File "/home/nair.ro/mlops-model-dev/src/XGBClassifier/pipeline/stage_03_training_cross_val.py", line 19, in main
    training.train(xgb)
  File "/home/nair.ro/mlops-model-dev/src/XGBClassifier/components/training.py", line 40, in train
    logger.info(f"Model training and cross validation initiated.")
NameError: name 'logger' is not defined
[2024-06-22 18:32:37,411: INFO: main: >>>>>> stage Data Ingestion stage started <<<<<<]
[2024-06-22 18:32:37,414: INFO: common: yaml file: config/config.yaml loaded successfully]
[2024-06-22 18:32:37,416: INFO: common: yaml file: params.yaml loaded successfully]
[2024-06-22 18:32:37,417: INFO: common: created directory at: artifacts]
[2024-06-22 18:32:37,418: INFO: common: created directory at: artifacts/data_ingestion]
[2024-06-22 18:32:37,419: INFO: data_ingestion: File already exists of size: ~ 74490 KB]
[2024-06-22 18:32:37,420: INFO: data_ingestion:  File 'artifacts/data_ingestion/card_transdata.csv' is of type '.csv']
[2024-06-22 18:32:37,420: INFO: main: >>>>>> stage Data Ingestion stage completed <<<<<<

x==========x]
[2024-06-22 18:32:37,420: INFO: main: *******************]
[2024-06-22 18:32:37,420: INFO: main: >>>>>> stage Prepare base model started <<<<<<]
[2024-06-22 18:32:37,422: INFO: common: yaml file: config/config.yaml loaded successfully]
[2024-06-22 18:32:37,424: INFO: common: yaml file: params.yaml loaded successfully]
[2024-06-22 18:32:37,425: INFO: common: created directory at: artifacts]
[2024-06-22 18:32:37,426: INFO: common: created directory at: artifacts/prepare_base_model]
[2024-06-22 18:32:37,426: INFO: prepare_base_model: Initialized XGBClassifier with following parameters PrepareBaseModelConfig(params_n_estimators=500, params_learning_rate=0.1, params_random_state=42, params_subsample=0.5, params_n_jobs=-1, params_max_depth=3)]
[2024-06-22 18:32:37,426: INFO: main: >>>>>> stage Prepare base model completed <<<<<<

x==========x]
[2024-06-22 18:32:37,426: INFO: main: *******************]
[2024-06-22 18:32:37,426: INFO: main: >>>>>> stage Train and save model started <<<<<<]
[2024-06-22 18:32:37,429: INFO: common: yaml file: config/config.yaml loaded successfully]
[2024-06-22 18:32:37,430: INFO: common: yaml file: params.yaml loaded successfully]
[2024-06-22 18:32:37,431: INFO: common: created directory at: artifacts]
[2024-06-22 18:32:37,432: INFO: common: created directory at: artifacts/training]
[2024-06-22 18:32:38,680: INFO: training: Model training and cross validation initiated.]
[2024-06-22 18:32:38,680: ERROR: main: name 'validate' is not defined]
Traceback (most recent call last):
  File "/home/nair.ro/mlops-model-dev/main.py", line 38, in <module>
    obj.main(xgb)
  File "/home/nair.ro/mlops-model-dev/src/XGBClassifier/pipeline/stage_03_training_cross_val.py", line 19, in main
    training.train(xgb)
  File "/home/nair.ro/mlops-model-dev/src/XGBClassifier/components/training.py", line 42, in train
    model = validate( xgb  ,X_train,y_train, self.config.params_scoring ,self.config.params_cv)
NameError: name 'validate' is not defined
[2024-06-22 18:33:16,252: INFO: main: >>>>>> stage Data Ingestion stage started <<<<<<]
[2024-06-22 18:33:16,255: INFO: common: yaml file: config/config.yaml loaded successfully]
[2024-06-22 18:33:16,261: INFO: common: yaml file: params.yaml loaded successfully]
[2024-06-22 18:33:16,262: INFO: common: created directory at: artifacts]
[2024-06-22 18:33:16,263: INFO: common: created directory at: artifacts/data_ingestion]
[2024-06-22 18:33:16,263: INFO: data_ingestion: File already exists of size: ~ 74490 KB]
[2024-06-22 18:33:16,265: INFO: data_ingestion:  File 'artifacts/data_ingestion/card_transdata.csv' is of type '.csv']
[2024-06-22 18:33:16,265: INFO: main: >>>>>> stage Data Ingestion stage completed <<<<<<

x==========x]
[2024-06-22 18:33:16,265: INFO: main: *******************]
[2024-06-22 18:33:16,266: INFO: main: >>>>>> stage Prepare base model started <<<<<<]
[2024-06-22 18:33:16,268: INFO: common: yaml file: config/config.yaml loaded successfully]
[2024-06-22 18:33:16,271: INFO: common: yaml file: params.yaml loaded successfully]
[2024-06-22 18:33:16,272: INFO: common: created directory at: artifacts]
[2024-06-22 18:33:16,272: INFO: common: created directory at: artifacts/prepare_base_model]
[2024-06-22 18:33:16,272: INFO: prepare_base_model: Initialized XGBClassifier with following parameters PrepareBaseModelConfig(params_n_estimators=500, params_learning_rate=0.1, params_random_state=42, params_subsample=0.5, params_n_jobs=-1, params_max_depth=3)]
[2024-06-22 18:33:16,273: INFO: main: >>>>>> stage Prepare base model completed <<<<<<

x==========x]
[2024-06-22 18:33:16,273: INFO: main: *******************]
[2024-06-22 18:33:16,273: INFO: main: >>>>>> stage Train and save model started <<<<<<]
[2024-06-22 18:33:16,276: INFO: common: yaml file: config/config.yaml loaded successfully]
[2024-06-22 18:33:16,278: INFO: common: yaml file: params.yaml loaded successfully]
[2024-06-22 18:33:16,279: INFO: common: created directory at: artifacts]
[2024-06-22 18:33:16,280: INFO: common: created directory at: artifacts/training]
[2024-06-22 18:33:17,659: INFO: training: Model training and cross validation initiated.]
[2024-06-22 18:33:17,660: ERROR: main: 'TrainingConfig' object has no attribute 'params_scoring']
Traceback (most recent call last):
  File "/home/nair.ro/mlops-model-dev/main.py", line 38, in <module>
    obj.main(xgb)
  File "/home/nair.ro/mlops-model-dev/src/XGBClassifier/pipeline/stage_03_training_cross_val.py", line 19, in main
    training.train(xgb)
  File "/home/nair.ro/mlops-model-dev/src/XGBClassifier/components/training.py", line 42, in train
    model = self.validate( xgb  ,X_train,y_train, self.config.params_scoring ,self.config.params_cv)
AttributeError: 'TrainingConfig' object has no attribute 'params_scoring'
[2024-06-22 18:34:38,721: INFO: main: >>>>>> stage Data Ingestion stage started <<<<<<]
[2024-06-22 18:34:38,724: INFO: common: yaml file: config/config.yaml loaded successfully]
[2024-06-22 18:34:38,726: INFO: common: yaml file: params.yaml loaded successfully]
[2024-06-22 18:34:38,727: INFO: common: created directory at: artifacts]
[2024-06-22 18:34:38,728: INFO: common: created directory at: artifacts/data_ingestion]
[2024-06-22 18:34:38,729: INFO: data_ingestion: File already exists of size: ~ 74490 KB]
[2024-06-22 18:34:38,730: INFO: data_ingestion:  File 'artifacts/data_ingestion/card_transdata.csv' is of type '.csv']
[2024-06-22 18:34:38,730: INFO: main: >>>>>> stage Data Ingestion stage completed <<<<<<

x==========x]
[2024-06-22 18:34:38,730: INFO: main: *******************]
[2024-06-22 18:34:38,730: INFO: main: >>>>>> stage Prepare base model started <<<<<<]
[2024-06-22 18:34:38,734: INFO: common: yaml file: config/config.yaml loaded successfully]
[2024-06-22 18:34:38,736: INFO: common: yaml file: params.yaml loaded successfully]
[2024-06-22 18:34:38,736: INFO: common: created directory at: artifacts]
[2024-06-22 18:34:38,737: INFO: common: created directory at: artifacts/prepare_base_model]
[2024-06-22 18:34:38,737: INFO: prepare_base_model: Initialized XGBClassifier with following parameters PrepareBaseModelConfig(params_n_estimators=500, params_learning_rate=0.1, params_random_state=42, params_subsample=0.5, params_n_jobs=-1, params_max_depth=3)]
[2024-06-22 18:34:38,738: INFO: main: >>>>>> stage Prepare base model completed <<<<<<

x==========x]
[2024-06-22 18:34:38,738: INFO: main: *******************]
[2024-06-22 18:34:38,738: INFO: main: >>>>>> stage Train and save model started <<<<<<]
[2024-06-22 18:34:38,740: INFO: common: yaml file: config/config.yaml loaded successfully]
[2024-06-22 18:34:38,743: INFO: common: yaml file: params.yaml loaded successfully]
[2024-06-22 18:34:38,743: INFO: common: created directory at: artifacts]
[2024-06-22 18:34:38,744: INFO: common: created directory at: artifacts/training]
[2024-06-22 18:34:40,293: INFO: training: Model training and cross validation initiated.]
[2024-06-22 18:34:40,293: ERROR: main: Training.validate() takes 5 positional arguments but 6 were given]
Traceback (most recent call last):
  File "/home/nair.ro/mlops-model-dev/main.py", line 38, in <module>
    obj.main(xgb)
  File "/home/nair.ro/mlops-model-dev/src/XGBClassifier/pipeline/stage_03_training_cross_val.py", line 19, in main
    training.train(xgb)
  File "/home/nair.ro/mlops-model-dev/src/XGBClassifier/components/training.py", line 42, in train
    model = self.validate( xgb  ,X_train,y_train, self.config.scoring ,self.config.cv)
TypeError: Training.validate() takes 5 positional arguments but 6 were given
[2024-06-22 18:36:34,207: INFO: main: >>>>>> stage Data Ingestion stage started <<<<<<]
[2024-06-22 18:36:34,210: INFO: common: yaml file: config/config.yaml loaded successfully]
[2024-06-22 18:36:34,213: INFO: common: yaml file: params.yaml loaded successfully]
[2024-06-22 18:36:34,214: INFO: common: created directory at: artifacts]
[2024-06-22 18:36:34,215: INFO: common: created directory at: artifacts/data_ingestion]
[2024-06-22 18:36:34,219: INFO: data_ingestion: File already exists of size: ~ 74490 KB]
[2024-06-22 18:36:34,220: INFO: data_ingestion:  File 'artifacts/data_ingestion/card_transdata.csv' is of type '.csv']
[2024-06-22 18:36:34,221: INFO: main: >>>>>> stage Data Ingestion stage completed <<<<<<

x==========x]
[2024-06-22 18:36:34,221: INFO: main: *******************]
[2024-06-22 18:36:34,221: INFO: main: >>>>>> stage Prepare base model started <<<<<<]
[2024-06-22 18:36:34,223: INFO: common: yaml file: config/config.yaml loaded successfully]
[2024-06-22 18:36:34,225: INFO: common: yaml file: params.yaml loaded successfully]
[2024-06-22 18:36:34,226: INFO: common: created directory at: artifacts]
[2024-06-22 18:36:34,231: INFO: common: created directory at: artifacts/prepare_base_model]
[2024-06-22 18:36:34,231: INFO: prepare_base_model: Initialized XGBClassifier with following parameters PrepareBaseModelConfig(params_n_estimators=500, params_learning_rate=0.1, params_random_state=42, params_subsample=0.5, params_n_jobs=-1, params_max_depth=3)]
[2024-06-22 18:36:34,232: INFO: main: >>>>>> stage Prepare base model completed <<<<<<

x==========x]
[2024-06-22 18:36:34,232: INFO: main: *******************]
[2024-06-22 18:36:34,232: INFO: main: >>>>>> stage Train and save model started <<<<<<]
[2024-06-22 18:36:34,235: INFO: common: yaml file: config/config.yaml loaded successfully]
[2024-06-22 18:36:34,240: INFO: common: yaml file: params.yaml loaded successfully]
[2024-06-22 18:36:34,242: INFO: common: created directory at: artifacts]
[2024-06-22 18:36:34,242: INFO: common: created directory at: artifacts/training]
[2024-06-22 18:36:35,618: INFO: training: Model training and cross validation initiated.]
[2024-06-22 18:38:21,264: INFO: training: Cross Validation Scores: [0.99063215 0.98941648 0.9902746  0.98820164 0.98905971]]
[2024-06-22 18:38:21,265: INFO: training: Scores Mean:  0.9895169155985206]
[2024-06-22 18:38:21,265: INFO: training: Scores Standard Deviation: 0.0008679747406873597]
[2024-06-22 18:38:44,916: INFO: training: Model saved in path artifacts/training/model.pkl.]
[2024-06-22 18:38:44,917: INFO: main: >>>>>> stage Train and save model completed <<<<<<

x==========x]
[2024-06-22 19:03:51,361: INFO: main: >>>>>> stage Data Ingestion stage started <<<<<<]
[2024-06-22 19:03:51,365: INFO: common: yaml file: config/config.yaml loaded successfully]
[2024-06-22 19:03:51,369: INFO: common: yaml file: params.yaml loaded successfully]
[2024-06-22 19:03:51,373: INFO: common: created directory at: artifacts]
[2024-06-22 19:03:51,377: INFO: common: created directory at: artifacts/data_ingestion]
[2024-06-22 19:03:55,699: INFO: data_ingestion:  file from url https://drive.google.com/uc?/export=download&id=1RmDs2j3QcY05ixoV1-ACmxmnM5xdmiGF downloaded and saved at path artifacts/data_ingestion/card_transdata.csv]
[2024-06-22 19:03:55,713: INFO: data_ingestion:  File 'artifacts/data_ingestion/card_transdata.csv' is of type '.csv']
[2024-06-22 19:03:55,713: INFO: main: >>>>>> stage Data Ingestion stage completed <<<<<<

x==========x]
[2024-06-22 19:03:55,713: INFO: main: *******************]
[2024-06-22 19:03:55,714: INFO: main: >>>>>> stage Prepare base model started <<<<<<]
[2024-06-22 19:03:55,717: INFO: common: yaml file: config/config.yaml loaded successfully]
[2024-06-22 19:03:55,719: INFO: common: yaml file: params.yaml loaded successfully]
[2024-06-22 19:03:55,720: INFO: common: created directory at: artifacts]
[2024-06-22 19:03:55,723: INFO: common: created directory at: artifacts/prepare_base_model]
[2024-06-22 19:03:55,724: INFO: prepare_base_model: Initialized XGBClassifier with following parameters PrepareBaseModelConfig(params_n_estimators=500, params_learning_rate=0.1, params_random_state=42, params_subsample=0.5, params_n_jobs=-1, params_max_depth=3)]
[2024-06-22 19:03:55,724: INFO: main: >>>>>> stage Prepare base model completed <<<<<<

x==========x]
[2024-06-22 19:03:55,725: INFO: main: *******************]
[2024-06-22 19:03:55,726: INFO: main: >>>>>> stage Train and save model started <<<<<<]
[2024-06-22 19:03:55,728: INFO: common: yaml file: config/config.yaml loaded successfully]
[2024-06-22 19:03:55,731: INFO: common: yaml file: params.yaml loaded successfully]
[2024-06-22 19:03:55,732: INFO: common: created directory at: artifacts]
[2024-06-22 19:03:55,734: INFO: common: created directory at: artifacts/training]
[2024-06-22 19:03:55,735: ERROR: main: TrainingConfig.__init__() missing 2 required positional arguments: 'stratify' and 'test_size']
Traceback (most recent call last):
  File "/home/nair.ro/mlops-model-dev/main.py", line 38, in <module>
    obj.main(xgb)
  File "/home/nair.ro/mlops-model-dev/src/XGBClassifier/pipeline/stage_03_training_cross_val.py", line 16, in main
    training_config = config.get_training_config()
  File "/home/nair.ro/mlops-model-dev/src/XGBClassifier/config_mngr/configuration_manager.py", line 63, in get_training_config
    training_config = TrainingConfig(
TypeError: TrainingConfig.__init__() missing 2 required positional arguments: 'stratify' and 'test_size'
[2024-06-22 19:04:55,013: INFO: main: >>>>>> stage Data Ingestion stage started <<<<<<]
[2024-06-22 19:04:55,016: INFO: common: yaml file: config/config.yaml loaded successfully]
[2024-06-22 19:04:55,018: INFO: common: yaml file: params.yaml loaded successfully]
[2024-06-22 19:04:55,020: INFO: common: created directory at: artifacts]
[2024-06-22 19:04:55,022: INFO: common: created directory at: artifacts/data_ingestion]
[2024-06-22 19:04:55,023: INFO: data_ingestion: File already exists of size: ~ 74490 KB]
[2024-06-22 19:04:55,025: INFO: data_ingestion:  File 'artifacts/data_ingestion/card_transdata.csv' is of type '.csv']
[2024-06-22 19:04:55,025: INFO: main: >>>>>> stage Data Ingestion stage completed <<<<<<

x==========x]
[2024-06-22 19:04:55,025: INFO: main: *******************]
[2024-06-22 19:04:55,026: INFO: main: >>>>>> stage Prepare base model started <<<<<<]
[2024-06-22 19:04:55,028: INFO: common: yaml file: config/config.yaml loaded successfully]
[2024-06-22 19:04:55,031: INFO: common: yaml file: params.yaml loaded successfully]
[2024-06-22 19:04:55,032: INFO: common: created directory at: artifacts]
[2024-06-22 19:04:55,033: INFO: common: created directory at: artifacts/prepare_base_model]
[2024-06-22 19:04:55,033: INFO: prepare_base_model: Initialized XGBClassifier with following parameters PrepareBaseModelConfig(params_n_estimators=500, params_learning_rate=0.1, params_random_state=42, params_subsample=0.5, params_n_jobs=-1, params_max_depth=3)]
[2024-06-22 19:04:55,033: INFO: main: >>>>>> stage Prepare base model completed <<<<<<

x==========x]
[2024-06-22 19:04:55,033: INFO: main: *******************]
[2024-06-22 19:04:55,034: INFO: main: >>>>>> stage Train and save model started <<<<<<]
[2024-06-22 19:04:55,036: INFO: common: yaml file: config/config.yaml loaded successfully]
[2024-06-22 19:04:55,041: INFO: common: yaml file: params.yaml loaded successfully]
[2024-06-22 19:04:55,041: INFO: common: created directory at: artifacts]
[2024-06-22 19:04:55,042: INFO: common: created directory at: artifacts/training]
[2024-06-22 19:04:55,983: ERROR: main: 'TrainingConfig' object has no attribute 'random_state']
Traceback (most recent call last):
  File "/home/nair.ro/mlops-model-dev/main.py", line 38, in <module>
    obj.main(xgb)
  File "/home/nair.ro/mlops-model-dev/src/XGBClassifier/pipeline/stage_03_training_cross_val.py", line 19, in main
    training.train(xgb)
  File "/home/nair.ro/mlops-model-dev/src/XGBClassifier/components/training.py", line 40, in train
    X_train , X_test ,y_train , y_test  = self.train_valid_generator()
  File "/home/nair.ro/mlops-model-dev/src/XGBClassifier/components/training.py", line 21, in train_valid_generator
    X_train , X_test ,y_train , y_test = train_test_split(X,y,test_size = self.config.test_size ,random_state =self.config.random_state  ,stratify=self.config.stratify)
AttributeError: 'TrainingConfig' object has no attribute 'random_state'
[2024-06-22 19:05:46,012: INFO: main: >>>>>> stage Data Ingestion stage started <<<<<<]
[2024-06-22 19:05:46,015: INFO: common: yaml file: config/config.yaml loaded successfully]
[2024-06-22 19:05:46,017: INFO: common: yaml file: params.yaml loaded successfully]
[2024-06-22 19:05:46,019: INFO: common: created directory at: artifacts]
[2024-06-22 19:05:46,020: INFO: common: created directory at: artifacts/data_ingestion]
[2024-06-22 19:05:46,022: INFO: data_ingestion: File already exists of size: ~ 74490 KB]
[2024-06-22 19:05:46,024: INFO: data_ingestion:  File 'artifacts/data_ingestion/card_transdata.csv' is of type '.csv']
[2024-06-22 19:05:46,024: INFO: main: >>>>>> stage Data Ingestion stage completed <<<<<<

x==========x]
[2024-06-22 19:05:46,025: INFO: main: *******************]
[2024-06-22 19:05:46,025: INFO: main: >>>>>> stage Prepare base model started <<<<<<]
[2024-06-22 19:05:46,027: INFO: common: yaml file: config/config.yaml loaded successfully]
[2024-06-22 19:05:46,030: INFO: common: yaml file: params.yaml loaded successfully]
[2024-06-22 19:05:46,030: INFO: common: created directory at: artifacts]
[2024-06-22 19:05:46,031: INFO: common: created directory at: artifacts/prepare_base_model]
[2024-06-22 19:05:46,031: INFO: prepare_base_model: Initialized XGBClassifier with following parameters PrepareBaseModelConfig(params_n_estimators=500, params_learning_rate=0.1, params_random_state=42, params_subsample=0.5, params_n_jobs=-1, params_max_depth=3)]
[2024-06-22 19:05:46,032: INFO: main: >>>>>> stage Prepare base model completed <<<<<<

x==========x]
[2024-06-22 19:05:46,032: INFO: main: *******************]
[2024-06-22 19:05:46,032: INFO: main: >>>>>> stage Train and save model started <<<<<<]
[2024-06-22 19:05:46,036: INFO: common: yaml file: config/config.yaml loaded successfully]
[2024-06-22 19:05:46,037: INFO: common: yaml file: params.yaml loaded successfully]
[2024-06-22 19:05:46,038: INFO: common: created directory at: artifacts]
[2024-06-22 19:05:46,039: INFO: common: created directory at: artifacts/training]
[2024-06-22 19:05:46,039: ERROR: main: TrainingConfig.__init__() got an unexpected keyword argument 'random_state']
Traceback (most recent call last):
  File "/home/nair.ro/mlops-model-dev/main.py", line 38, in <module>
    obj.main(xgb)
  File "/home/nair.ro/mlops-model-dev/src/XGBClassifier/pipeline/stage_03_training_cross_val.py", line 16, in main
    training_config = config.get_training_config()
  File "/home/nair.ro/mlops-model-dev/src/XGBClassifier/config_mngr/configuration_manager.py", line 63, in get_training_config
    training_config = TrainingConfig(
TypeError: TrainingConfig.__init__() got an unexpected keyword argument 'random_state'
[2024-06-22 19:08:44,289: INFO: main: >>>>>> stage Data Ingestion stage started <<<<<<]
[2024-06-22 19:08:44,291: INFO: common: yaml file: config/config.yaml loaded successfully]
[2024-06-22 19:08:44,293: INFO: common: yaml file: params.yaml loaded successfully]
[2024-06-22 19:08:44,295: INFO: common: created directory at: artifacts]
[2024-06-22 19:08:44,296: INFO: common: created directory at: artifacts/data_ingestion]
[2024-06-22 19:08:44,297: INFO: data_ingestion: File already exists of size: ~ 74490 KB]
[2024-06-22 19:08:44,298: INFO: data_ingestion:  File 'artifacts/data_ingestion/card_transdata.csv' is of type '.csv']
[2024-06-22 19:08:44,298: INFO: main: >>>>>> stage Data Ingestion stage completed <<<<<<

x==========x]
[2024-06-22 19:08:44,299: INFO: main: *******************]
[2024-06-22 19:08:44,299: INFO: main: >>>>>> stage Prepare base model started <<<<<<]
[2024-06-22 19:08:44,301: INFO: common: yaml file: config/config.yaml loaded successfully]
[2024-06-22 19:08:44,303: INFO: common: yaml file: params.yaml loaded successfully]
[2024-06-22 19:08:44,304: INFO: common: created directory at: artifacts]
[2024-06-22 19:08:44,305: INFO: common: created directory at: artifacts/prepare_base_model]
[2024-06-22 19:08:44,305: INFO: prepare_base_model: Initialized XGBClassifier with following parameters PrepareBaseModelConfig(params_n_estimators=500, params_learning_rate=0.1, params_random_state=42, params_subsample=0.5, params_n_jobs=-1, params_max_depth=3)]
[2024-06-22 19:08:44,305: INFO: main: >>>>>> stage Prepare base model completed <<<<<<

x==========x]
[2024-06-22 19:08:44,305: INFO: main: *******************]
[2024-06-22 19:08:44,305: INFO: main: >>>>>> stage Train and save model started <<<<<<]
[2024-06-22 19:08:44,308: INFO: common: yaml file: config/config.yaml loaded successfully]
[2024-06-22 19:08:44,310: INFO: common: yaml file: params.yaml loaded successfully]
[2024-06-22 19:08:44,311: INFO: common: created directory at: artifacts]
[2024-06-22 19:08:44,312: INFO: common: created directory at: artifacts/training]
[2024-06-22 19:08:45,192: ERROR: main: The 'stratify' parameter of train_test_split must be an array-like or None. Got 'y' instead.]
Traceback (most recent call last):
  File "/home/nair.ro/mlops-model-dev/main.py", line 38, in <module>
    obj.main(xgb)
  File "/home/nair.ro/mlops-model-dev/src/XGBClassifier/pipeline/stage_03_training_cross_val.py", line 19, in main
    training.train(xgb)
  File "/home/nair.ro/mlops-model-dev/src/XGBClassifier/components/training.py", line 40, in train
    X_train , X_test ,y_train , y_test  = self.train_valid_generator()
  File "/home/nair.ro/mlops-model-dev/src/XGBClassifier/components/training.py", line 21, in train_valid_generator
    X_train , X_test ,y_train , y_test = train_test_split(X,y,test_size = self.config.test_size ,random_state =self.config.random_state  ,stratify=self.config.stratify)
  File "/home/nair.ro/miniforge3/lib/python3.10/site-packages/sklearn/utils/_param_validation.py", line 203, in wrapper
    validate_parameter_constraints(
  File "/home/nair.ro/miniforge3/lib/python3.10/site-packages/sklearn/utils/_param_validation.py", line 95, in validate_parameter_constraints
    raise InvalidParameterError(
sklearn.utils._param_validation.InvalidParameterError: The 'stratify' parameter of train_test_split must be an array-like or None. Got 'y' instead.
[2024-06-22 19:11:26,363: INFO: main: >>>>>> stage Data Ingestion stage started <<<<<<]
[2024-06-22 19:11:26,365: INFO: common: yaml file: config/config.yaml loaded successfully]
[2024-06-22 19:11:26,368: INFO: common: yaml file: params.yaml loaded successfully]
[2024-06-22 19:11:26,369: INFO: common: created directory at: artifacts]
[2024-06-22 19:11:26,369: INFO: common: created directory at: artifacts/data_ingestion]
[2024-06-22 19:11:26,370: INFO: data_ingestion: File already exists of size: ~ 74490 KB]
[2024-06-22 19:11:26,372: INFO: data_ingestion:  File 'artifacts/data_ingestion/card_transdata.csv' is of type '.csv']
[2024-06-22 19:11:26,372: INFO: main: >>>>>> stage Data Ingestion stage completed <<<<<<

x==========x]
[2024-06-22 19:11:26,372: INFO: main: *******************]
[2024-06-22 19:11:26,372: INFO: main: >>>>>> stage Prepare base model started <<<<<<]
[2024-06-22 19:11:26,376: INFO: common: yaml file: config/config.yaml loaded successfully]
[2024-06-22 19:11:26,377: INFO: common: yaml file: params.yaml loaded successfully]
[2024-06-22 19:11:26,380: INFO: common: created directory at: artifacts]
[2024-06-22 19:11:26,381: INFO: common: created directory at: artifacts/prepare_base_model]
[2024-06-22 19:11:26,381: INFO: prepare_base_model: Initialized XGBClassifier with following parameters PrepareBaseModelConfig(params_n_estimators=500, params_learning_rate=0.1, params_random_state=42, params_subsample=0.5, params_n_jobs=-1, params_max_depth=3)]
[2024-06-22 19:11:26,381: INFO: main: >>>>>> stage Prepare base model completed <<<<<<

x==========x]
[2024-06-22 19:11:26,382: INFO: main: *******************]
[2024-06-22 19:11:26,382: INFO: main: >>>>>> stage Train and save model started <<<<<<]
[2024-06-22 19:11:26,384: INFO: common: yaml file: config/config.yaml loaded successfully]
[2024-06-22 19:11:26,387: INFO: common: yaml file: params.yaml loaded successfully]
[2024-06-22 19:11:26,387: INFO: common: created directory at: artifacts]
[2024-06-22 19:11:26,388: INFO: common: created directory at: artifacts/training]
[2024-06-22 19:11:27,649: INFO: training: Model training and cross validation initiated.]
[2024-06-22 19:13:17,737: INFO: training: Cross Validation Scores: [0.99063215 0.98941648 0.9902746  0.98820164 0.98905971]]
[2024-06-22 19:13:17,738: INFO: training: Scores Mean:  0.9895169155985206]
[2024-06-22 19:13:17,739: INFO: training: Scores Standard Deviation: 0.0008679747406873597]
[2024-06-22 19:13:47,031: INFO: training: Model saved in path artifacts/training/model.pkl.]
[2024-06-22 19:13:47,032: INFO: main: >>>>>> stage Train and save model completed <<<<<<

x==========x]
[2024-06-22 19:43:11,275: INFO: main: >>>>>> stage Data Ingestion stage started <<<<<<]
[2024-06-22 19:43:11,279: INFO: common: yaml file: config/config.yaml loaded successfully]
[2024-06-22 19:43:11,283: INFO: common: yaml file: params.yaml loaded successfully]
[2024-06-22 19:43:11,283: INFO: common: created directory at: artifacts]
[2024-06-22 19:43:11,284: INFO: common: created directory at: artifacts/data_ingestion]
[2024-06-22 19:43:11,285: INFO: data_ingestion: File already exists of size: ~ 74490 KB]
[2024-06-22 19:43:11,286: INFO: data_ingestion:  File 'artifacts/data_ingestion/card_transdata.csv' is of type '.csv']
[2024-06-22 19:43:11,286: INFO: main: >>>>>> stage Data Ingestion stage completed <<<<<<

x==========x]
[2024-06-22 19:43:11,286: INFO: main: *******************]
[2024-06-22 19:43:11,287: INFO: main: >>>>>> stage Prepare base model started <<<<<<]
[2024-06-22 19:43:11,290: INFO: common: yaml file: config/config.yaml loaded successfully]
[2024-06-22 19:43:11,292: INFO: common: yaml file: params.yaml loaded successfully]
[2024-06-22 19:43:11,292: INFO: common: created directory at: artifacts]
[2024-06-22 19:43:11,293: INFO: common: created directory at: artifacts/prepare_base_model]
[2024-06-22 19:43:11,293: INFO: prepare_base_model: Initialized XGBClassifier with following parameters PrepareBaseModelConfig(params_n_estimators=500, params_learning_rate=0.1, params_random_state=42, params_subsample=0.5, params_n_jobs=-1, params_max_depth=3)]
[2024-06-22 19:43:11,293: INFO: main: >>>>>> stage Prepare base model completed <<<<<<

x==========x]
[2024-06-22 19:43:11,294: INFO: main: *******************]
[2024-06-22 19:43:11,294: INFO: main: >>>>>> stage Train and save model started <<<<<<]
[2024-06-22 19:43:11,297: INFO: common: yaml file: config/config.yaml loaded successfully]
[2024-06-22 19:43:11,299: INFO: common: yaml file: params.yaml loaded successfully]
[2024-06-22 19:43:11,300: INFO: common: created directory at: artifacts]
[2024-06-22 19:43:11,301: INFO: common: created directory at: artifacts/training]
[2024-06-22 19:43:12,694: INFO: training: Model training and cross validation initiated.]
[2024-06-22 19:44:57,939: INFO: training: Cross Validation Scores: [0.99063215 0.98941648 0.9902746  0.98820164 0.98905971]]
[2024-06-22 19:44:57,940: INFO: training: Scores Mean:  0.9895169155985206]
[2024-06-22 19:44:57,940: INFO: training: Scores Standard Deviation: 0.0008679747406873597]
[2024-06-22 19:45:21,836: INFO: training: Model saved in path artifacts/training/model.pkl.]
[2024-06-22 19:45:21,837: INFO: main: >>>>>> stage Train and save model completed <<<<<<

x==========x]
[2024-06-22 19:45:21,837: INFO: main: *******************]
[2024-06-22 19:45:21,837: INFO: main: >>>>>> stage Evaluation stage started <<<<<<]
[2024-06-22 19:45:21,837: ERROR: main: name 'EvaluationPipeline' is not defined]
Traceback (most recent call last):
  File "/home/nair.ro/mlops-model-dev/main.py", line 51, in <module>
    model_evalution = EvaluationPipeline()
NameError: name 'EvaluationPipeline' is not defined
[2024-06-22 19:52:25,482: INFO: main: >>>>>> stage Data Ingestion stage started <<<<<<]
[2024-06-22 19:52:25,489: INFO: common: yaml file: config/config.yaml loaded successfully]
[2024-06-22 19:52:25,493: INFO: common: yaml file: params.yaml loaded successfully]
[2024-06-22 19:52:25,494: INFO: common: created directory at: artifacts]
[2024-06-22 19:52:25,495: INFO: common: created directory at: artifacts/data_ingestion]
[2024-06-22 19:52:25,497: INFO: data_ingestion: File already exists of size: ~ 74490 KB]
[2024-06-22 19:52:25,500: INFO: data_ingestion:  File 'artifacts/data_ingestion/card_transdata.csv' is of type '.csv']
[2024-06-22 19:52:25,500: INFO: main: >>>>>> stage Data Ingestion stage completed <<<<<<

x==========x]
[2024-06-22 19:52:25,501: INFO: main: *******************]
[2024-06-22 19:52:25,502: INFO: main: >>>>>> stage Prepare base model started <<<<<<]
[2024-06-22 19:52:25,506: INFO: common: yaml file: config/config.yaml loaded successfully]
[2024-06-22 19:52:25,509: INFO: common: yaml file: params.yaml loaded successfully]
[2024-06-22 19:52:25,511: INFO: common: created directory at: artifacts]
[2024-06-22 19:52:25,513: INFO: common: created directory at: artifacts/prepare_base_model]
[2024-06-22 19:52:25,513: INFO: prepare_base_model: Initialized XGBClassifier with following parameters PrepareBaseModelConfig(params_n_estimators=500, params_learning_rate=0.1, params_random_state=42, params_subsample=0.5, params_n_jobs=-1, params_max_depth=3)]
[2024-06-22 19:52:25,513: INFO: main: >>>>>> stage Prepare base model completed <<<<<<

x==========x]
[2024-06-22 19:52:25,514: INFO: main: *******************]
[2024-06-22 19:52:25,514: INFO: main: >>>>>> stage Train and save model started <<<<<<]
[2024-06-22 19:52:25,519: INFO: common: yaml file: config/config.yaml loaded successfully]
[2024-06-22 19:52:25,522: INFO: common: yaml file: params.yaml loaded successfully]
[2024-06-22 19:52:25,523: INFO: common: created directory at: artifacts]
[2024-06-22 19:52:25,527: INFO: common: created directory at: artifacts/training]
[2024-06-22 19:52:27,250: INFO: training: Model training and cross validation initiated.]
[2024-06-22 19:54:13,200: INFO: training: Cross Validation Scores: [0.99063215 0.98941648 0.9902746  0.98820164 0.98905971]]
[2024-06-22 19:54:13,203: INFO: training: Scores Mean:  0.9895169155985206]
[2024-06-22 19:54:13,203: INFO: training: Scores Standard Deviation: 0.0008679747406873597]
[2024-06-22 19:54:37,229: INFO: training: Model saved in path artifacts/training/model.pkl.]
[2024-06-22 19:54:37,232: INFO: main: >>>>>> stage Train and save model completed <<<<<<

x==========x]
[2024-06-22 19:54:37,232: INFO: main: *******************]
[2024-06-22 19:54:37,232: INFO: main: >>>>>> stage Evaluation stage started <<<<<<]
[2024-06-22 19:54:37,232: ERROR: main: name 'model_evaluation' is not defined]
Traceback (most recent call last):
  File "/home/nair.ro/mlops-model-dev/main.py", line 52, in <module>
    model_evalution.main(xgb)
  File "/home/nair.ro/mlops-model-dev/src/XGBClassifier/pipeline/stage_04_evaluation.py", line 15, in main
    model_evaluation(xgb)
NameError: name 'model_evaluation' is not defined
[2024-06-22 19:57:30,148: INFO: main: >>>>>> stage Data Ingestion stage started <<<<<<]
[2024-06-22 19:57:30,152: INFO: common: yaml file: config/config.yaml loaded successfully]
[2024-06-22 19:57:30,156: INFO: common: yaml file: params.yaml loaded successfully]
[2024-06-22 19:57:30,157: INFO: common: created directory at: artifacts]
[2024-06-22 19:57:30,159: INFO: common: created directory at: artifacts/data_ingestion]
[2024-06-22 19:57:30,160: INFO: data_ingestion: File already exists of size: ~ 74490 KB]
[2024-06-22 19:57:30,161: INFO: data_ingestion:  File 'artifacts/data_ingestion/card_transdata.csv' is of type '.csv']
[2024-06-22 19:57:30,161: INFO: main: >>>>>> stage Data Ingestion stage completed <<<<<<

x==========x]
[2024-06-22 19:57:30,162: INFO: main: *******************]
[2024-06-22 19:57:30,162: INFO: main: >>>>>> stage Prepare base model started <<<<<<]
[2024-06-22 19:57:30,165: INFO: common: yaml file: config/config.yaml loaded successfully]
[2024-06-22 19:57:30,167: INFO: common: yaml file: params.yaml loaded successfully]
[2024-06-22 19:57:30,173: INFO: common: created directory at: artifacts]
[2024-06-22 19:57:30,173: INFO: common: created directory at: artifacts/prepare_base_model]
[2024-06-22 19:57:30,174: INFO: prepare_base_model: Initialized XGBClassifier with following parameters PrepareBaseModelConfig(params_n_estimators=500, params_learning_rate=0.1, params_random_state=42, params_subsample=0.5, params_n_jobs=-1, params_max_depth=3)]
[2024-06-22 19:57:30,174: INFO: main: >>>>>> stage Prepare base model completed <<<<<<

x==========x]
[2024-06-22 19:57:30,174: INFO: main: *******************]
[2024-06-22 19:57:30,175: INFO: main: >>>>>> stage Train and save model started <<<<<<]
[2024-06-22 19:57:30,177: INFO: common: yaml file: config/config.yaml loaded successfully]
[2024-06-22 19:57:30,180: INFO: common: yaml file: params.yaml loaded successfully]
[2024-06-22 19:57:30,181: INFO: common: created directory at: artifacts]
[2024-06-22 19:57:30,181: INFO: common: created directory at: artifacts/training]
[2024-06-22 19:57:31,449: INFO: training: Model training and cross validation initiated.]
[2024-06-22 19:59:17,079: INFO: training: Cross Validation Scores: [0.99063215 0.98941648 0.9902746  0.98820164 0.98905971]]
[2024-06-22 19:59:17,080: INFO: training: Scores Mean:  0.9895169155985206]
[2024-06-22 19:59:17,081: INFO: training: Scores Standard Deviation: 0.0008679747406873597]
[2024-06-22 19:59:41,565: INFO: training: Model saved in path artifacts/training/model.pkl.]
[2024-06-22 19:59:41,566: INFO: main: >>>>>> stage Train and save model completed <<<<<<

x==========x]
[2024-06-22 19:59:41,566: INFO: main: *******************]
[2024-06-22 19:59:41,566: INFO: main: >>>>>> stage Evaluation stage started <<<<<<]
[2024-06-22 19:59:41,567: ERROR: main: name 'model_evaluation' is not defined]
Traceback (most recent call last):
  File "/home/nair.ro/mlops-model-dev/main.py", line 52, in <module>
    model_evalution.main(xgb)
  File "/home/nair.ro/mlops-model-dev/src/XGBClassifier/pipeline/stage_04_evaluation.py", line 17, in main
    model_evaluation(xgb)
NameError: name 'model_evaluation' is not defined
[2024-06-22 20:00:43,869: INFO: main: >>>>>> stage Data Ingestion stage started <<<<<<]
[2024-06-22 20:00:43,872: INFO: common: yaml file: config/config.yaml loaded successfully]
[2024-06-22 20:00:43,876: INFO: common: yaml file: params.yaml loaded successfully]
[2024-06-22 20:00:43,877: INFO: common: created directory at: artifacts]
[2024-06-22 20:00:43,882: INFO: common: created directory at: artifacts/data_ingestion]
[2024-06-22 20:00:43,883: INFO: data_ingestion: File already exists of size: ~ 74490 KB]
[2024-06-22 20:00:43,885: INFO: data_ingestion:  File 'artifacts/data_ingestion/card_transdata.csv' is of type '.csv']
[2024-06-22 20:00:43,885: INFO: main: >>>>>> stage Data Ingestion stage completed <<<<<<

x==========x]
[2024-06-22 20:00:43,886: INFO: main: *******************]
[2024-06-22 20:00:43,886: INFO: main: >>>>>> stage Prepare base model started <<<<<<]
[2024-06-22 20:00:43,890: INFO: common: yaml file: config/config.yaml loaded successfully]
[2024-06-22 20:00:43,892: INFO: common: yaml file: params.yaml loaded successfully]
[2024-06-22 20:00:43,893: INFO: common: created directory at: artifacts]
[2024-06-22 20:00:43,894: INFO: common: created directory at: artifacts/prepare_base_model]
[2024-06-22 20:00:43,895: INFO: prepare_base_model: Initialized XGBClassifier with following parameters PrepareBaseModelConfig(params_n_estimators=500, params_learning_rate=0.1, params_random_state=42, params_subsample=0.5, params_n_jobs=-1, params_max_depth=3)]
[2024-06-22 20:00:43,895: INFO: main: >>>>>> stage Prepare base model completed <<<<<<

x==========x]
[2024-06-22 20:00:43,895: INFO: main: *******************]
[2024-06-22 20:00:43,895: INFO: main: >>>>>> stage Train and save model started <<<<<<]
[2024-06-22 20:00:43,898: INFO: common: yaml file: config/config.yaml loaded successfully]
[2024-06-22 20:00:43,901: INFO: common: yaml file: params.yaml loaded successfully]
[2024-06-22 20:00:43,903: INFO: common: created directory at: artifacts]
[2024-06-22 20:00:43,904: INFO: common: created directory at: artifacts/training]
[2024-06-22 20:00:45,181: INFO: training: Model training and cross validation initiated.]
[2024-06-22 20:02:59,773: INFO: training: Cross Validation Scores: [0.99063215 0.98941648 0.9902746  0.98820164 0.98905971]]
[2024-06-22 20:02:59,773: INFO: training: Scores Mean:  0.9895169155985206]
[2024-06-22 20:02:59,775: INFO: training: Scores Standard Deviation: 0.0008679747406873597]
[2024-06-22 20:03:24,197: INFO: training: Model saved in path artifacts/training/model.pkl.]
[2024-06-22 20:03:24,198: INFO: main: >>>>>> stage Train and save model completed <<<<<<

x==========x]
[2024-06-22 20:03:24,202: INFO: main: *******************]
[2024-06-22 20:03:24,205: INFO: main: >>>>>> stage Evaluation stage started <<<<<<]
[2024-06-22 20:03:24,207: ERROR: main: Evaluation.__init__() missing 1 required positional argument: 'config']
Traceback (most recent call last):
  File "/home/nair.ro/mlops-model-dev/main.py", line 52, in <module>
    model_evalution.main(xgb)
  File "/home/nair.ro/mlops-model-dev/src/XGBClassifier/pipeline/stage_04_evaluation.py", line 16, in main
    evalu = Evaluation()
TypeError: Evaluation.__init__() missing 1 required positional argument: 'config'
[2024-06-22 20:03:58,453: INFO: main: >>>>>> stage Data Ingestion stage started <<<<<<]
[2024-06-22 20:03:58,457: INFO: common: yaml file: config/config.yaml loaded successfully]
[2024-06-22 20:03:58,460: INFO: common: yaml file: params.yaml loaded successfully]
[2024-06-22 20:03:58,461: INFO: common: created directory at: artifacts]
[2024-06-22 20:03:58,463: INFO: common: created directory at: artifacts/data_ingestion]
[2024-06-22 20:03:58,464: INFO: data_ingestion: File already exists of size: ~ 74490 KB]
[2024-06-22 20:03:58,467: INFO: data_ingestion:  File 'artifacts/data_ingestion/card_transdata.csv' is of type '.csv']
[2024-06-22 20:03:58,467: INFO: main: >>>>>> stage Data Ingestion stage completed <<<<<<

x==========x]
[2024-06-22 20:03:58,469: INFO: main: *******************]
[2024-06-22 20:03:58,470: INFO: main: >>>>>> stage Prepare base model started <<<<<<]
[2024-06-22 20:03:58,475: INFO: common: yaml file: config/config.yaml loaded successfully]
[2024-06-22 20:03:58,478: INFO: common: yaml file: params.yaml loaded successfully]
[2024-06-22 20:03:58,479: INFO: common: created directory at: artifacts]
[2024-06-22 20:03:58,481: INFO: common: created directory at: artifacts/prepare_base_model]
[2024-06-22 20:03:58,482: INFO: prepare_base_model: Initialized XGBClassifier with following parameters PrepareBaseModelConfig(params_n_estimators=500, params_learning_rate=0.1, params_random_state=42, params_subsample=0.5, params_n_jobs=-1, params_max_depth=3)]
[2024-06-22 20:03:58,484: INFO: main: >>>>>> stage Prepare base model completed <<<<<<

x==========x]
[2024-06-22 20:03:58,485: INFO: main: *******************]
[2024-06-22 20:03:58,487: INFO: main: >>>>>> stage Train and save model started <<<<<<]
[2024-06-22 20:03:58,493: INFO: common: yaml file: config/config.yaml loaded successfully]
[2024-06-22 20:03:58,496: INFO: common: yaml file: params.yaml loaded successfully]
[2024-06-22 20:03:58,498: INFO: common: created directory at: artifacts]
[2024-06-22 20:03:58,498: INFO: common: created directory at: artifacts/training]
[2024-06-22 20:03:59,988: INFO: training: Model training and cross validation initiated.]
[2024-06-22 20:05:45,885: INFO: training: Cross Validation Scores: [0.99063215 0.98941648 0.9902746  0.98820164 0.98905971]]
[2024-06-22 20:05:45,886: INFO: training: Scores Mean:  0.9895169155985206]
[2024-06-22 20:05:45,888: INFO: training: Scores Standard Deviation: 0.0008679747406873597]
[2024-06-22 20:06:10,071: INFO: training: Model saved in path artifacts/training/model.pkl.]
[2024-06-22 20:06:10,072: INFO: main: >>>>>> stage Train and save model completed <<<<<<

x==========x]
[2024-06-22 20:06:10,074: INFO: main: *******************]
[2024-06-22 20:06:10,075: INFO: main: >>>>>> stage Evaluation stage started <<<<<<]
[2024-06-22 20:06:10,077: ERROR: main: Evaluation.__init__() missing 1 required positional argument: 'config']
Traceback (most recent call last):
  File "/home/nair.ro/mlops-model-dev/main.py", line 52, in <module>
    model_evalution.main(xgb)
  File "/home/nair.ro/mlops-model-dev/src/XGBClassifier/pipeline/stage_04_evaluation.py", line 16, in main
    evalu = Evaluation()
TypeError: Evaluation.__init__() missing 1 required positional argument: 'config'
